Workbook

Sheet Team based gains
A1: Team/person based efficiency calcs | D1: Design system team size/cost | G1: Product team example
A3: Number of UI developers | D3: Developers | E3: 4 | G3: Developers | H3: 20
A4: Number of designers | D4: Designers | E4: 2 | G4: Designers | H4: 10
A6: Avg UI developer salary | B6: 116576 | D6: Developer cost | E6: =sum(E3*B6*B8) -> 582880 | G6: Developer cost | H6: =sum((H3*B6)*B8) -> 2914400
A7: Avg designer salary | B7: 79854 | D7: Designer cost | E7: =sum(E4*B7*B8) -> 199635 | G7: Designer cost | H7: =sum(H4*B7*B8) -> 998175
A8: Load cost multiplier | B8: 1.25 | D8: Total cost | E8: =sum(E6:E7) -> 782515 | G8: Total cost | H8: =sum(H6:H7) -> 3912575
A10: Developer efficiency gain | B10: 0.38 | G10: Efficiency gain | H10: =sum(((B10*20)+(B11*10))/30) -> 0.35666667
A11: Designer efficiency gain | B11: 0.31 | G11: Opportunity cost saving | H11: =sum(H8*H10) -> 1395485.1
G13: Savings versus design team cost | H13: =sum(H11-E8) -> 612970.08

Sheet Knapsack platform efficiency
A1: System maintenance load
A4: At design system team size... | B4: Bespoke | C4: Knapsack
A5: 3 | B5: 0.25 | C5: 0.2
A6: 6 | B6: 0.2 | C6: 0.15
A7: 10 | B7: 0.18 | C7: 0.1
A8: 15 | B8: 0.175 | C8: 0.07
A9: 20 | B9: 0.175 | C9: 0.05
A11: Foundation of calculations:
A12: Bespoke platforms require ongoing dev/ops/content support - it scales slowly down, but will plateau
A13: Knapsack platform benefits from hosted infra, built in scaffolds, self-serve consumption, less tooling sprawl
A16: DS team efficiency - Knapsack versus bespoke, realized by org. maturity
A18: Scenario | B18: # product teams supported (approx.) | C18: Bespoke DS team size | D18: Product teams per FTE (Bespoke) | E18: Knapsack DS team size (est) | F18: Product teams per FTE (Knapsack) | G18: Efficiency improvement | H18: Notes
A19: IBM (Carbon) | B19: 225 | C19: 22 | D19: =sum(B19/C19) -> 10.227273 | E19: =sum(C19/1.2) -> 18.333333 | F19: =sum(B19/E19) -> 12.272727 | G19: =sum((F19/D19)-1) -> 0.2 | H19: A benchmark in operational efficiency
A20: Mid-range enterprise | B20: 60 | C20: 12 | D20: =sum(B20/C20) -> 5 | E20: =sum(C20/1.2) -> 10 | F20: =sum(B20/E20) -> 6 | G20: =sum((F20/D20)-1) -> 0.2
A21: Chase | B21: 100 | C21: 80 | D21: =sum(B21/C21) -> 1.25 | E21: =sum(C21/1.2) -> 66.666667 | F21: =sum(B21/E21) -> 1.5 | G21: =sum((F21/D21)-1) -> 0.2 | H21: A very large DS team, especially for # of products
A23: Notes: This is the potential immediate infrastructure efficiency gains, and assumes no change in the operational efficiency of the customer.
A25: Hypothetical scenario
A26: Chase engages Knapsack to become their design system platform, but also works with Knapsack's proserv and increase operational efficiency to 60% of IBM's level.
A28: Chase | B28: 100 | C28: =sum(C21*0.6) -> 48 | D28: =sum(B28/C28) -> 2.0833333 | E28: =sum(C28/1.2) -> 40 | F28: =sum(B28/E28) -> 2.5 | G28: =sum((F28/D21)-1) -> 1
A30: Extrapolated formula
A31: Design system maturity | B31: Name | C31: Description | D31: Product Teams per FTE (Bespoke) | E31: Product Teams per FTE (Knapsack) | F31: Multiplier | G31: Compounded multiplier | I31: Adoption | J31: Efficiency gain
A32: 1 | B32: Fragmented / Ad Hoc | C32: No consistent system usage; duplicative tools, reactive work | D32: 2 | E32: =sum(D32*1.2) -> 2.4 | F32: =sum(E32/D32) -> 1.2 | I32: 0.2 | J32: =sum(J35*(I32/I35)) -> 0.0225
A33: 2 | B33: Documented but Manual | C33: Has guidance, but no enforcement; Figma-to-code handoff still dominant | D33: 4 | E33: =sum(D33*1.2) -> 4.8 | F33: =sum(E33/D33) -> 1.2 | G33: =sum(E33/E32) -> 2 | I33: 0.4 | J33: =sum(J35*(I33/I35)) -> 0.045
A34: 3 | B34: Governed & Adopted | C34: Design system is enforced, broadly adopted; teams align to DS patterns | D34: 6 | E34: =sum(D34*1.2) -> 7.2 | F34: =sum(E34/D34) -> 1.2 | G34: =sum(E34/E32) -> 3 | I34: 0.6 | J34: =sum(J35*(I34/I35)) -> 0.0675
A35: 4 | B35: Integrated into Delivery | C35: System is part of CI/CD, components tokenized, teams onboarded consistently | D35: 8 | E35: =sum(D35*1.2) -> 9.6 | F35: =sum(E35/D35) -> 1.2 | G35: =sum(E35/E32) -> 4 | I35: 0.8 | J35: =sum(Calculator!E6) -> 0.09
A36: 5 | B36: Orchestrated / Optimized | C36: Governance + delivery model is intelligent, integrated, and scalable | D36: 10 | E36: =sum(D36*1.2) -> 12 | F36: =sum(E36/D36) -> 1.2 | G36: =sum(E36/E32) -> 5 | I36: 1 | J36: =sum(J35*(I36/I35)) -> 0.1125

Sheet Intelligent product engine
A1: Dimension | B1: Traditional Design System (Canvas-led) | C1: Knapsack Intelligent Product Engine
A2: Starting Point | B2: Design happens in a canvas (Figma, etc.) | C2: Existing product artifacts are ingested into structured models
A3: Design/Dev Handoff | B3: Relies on mockups passed to developers | C3: Skipped entirely — composition happens in or near code
A4: System Governance | B4: Manual, reference-based governance enforcement | C4: Embedded in the MCP and applied through validation + rules
A5: Component Composition | B5: Manual implementation by engineers from design specs | C5: AI-assisted composition assistant uses tokens, components, and patterns
A6: Cycle Time | B6: Long — design, spec, review, dev, re-review | C6: Short — assisted, structured generation with shared context
A7: Version 1 Output | B7: Coded manually by dev team after back-and-forth iteration | C7: First version generated rapidly with contextual design system knowledge
A8: Release Path | B8: Multi-step refinement → eventual release | C8: V1 product is reviewed, optionally refined, then released
A9: Efficiency Scaling | B9: High headcount required for alignment, documentation, ops | C9: Low headcount needed — alignment and documentation are emergent
A10: Tooling Footprint | B10: Disconnected tools: Figma, Storybook, Confluence, internal wikis | C10: Unified via Knapsack MCP + agent ecosystem
A11: Governance Model | B11: Reference governance: “Did you follow the design system?” | C11: Embedded governance: system itself enforces structure
A13: Hypothesis
B14: Traditional (Canvas + DS) | C14: Knapsack IPE | D14: Efficiency gain
A15: Create design/spec | B15: 10 | C15: 2 | D15: =sum(B15/C15) -> 5
A16: Dev handoff/implement | B16: 21 | C16: 2 | D16: =sum(B16/C16) -> 10.5
A17: Review + iteration | B17: 14 | C17: 2 | D17: =sum(B17/C17) -> 7
A18: Integrate / prep / release | B18: 8 | C18: 1 | D18: =sum(B18/C18) -> 8
A19: Cycle time | B19: =sum(B15:B18) -> 53 | C19: =sum(C15:C18) -> 7 | D19: =sum(B19/C19) -> 7.5714286
A23: Extra special math...
A24: Chase adopts Knapsack, adopts ops improvement, then uses the IPE... | D24: 66.29

Sheet Calculator
A1: ACME Company
A3: Product ROI multiplier | B3: 3 | D3: We assume a baseline product ROI of 3×, a conservative industry standard representing typical value delivery for non-optimized teams. This aligns with internal benchmarks used in mid-sized enterprises and is consistent with expectations from strategy consulting and innovation portfolio modeling.
A5: Product teams | G5: Adopt Knapsack as DS platform | J5: DS cost to product team efficiency multiplier
A6: # product teams | B6: 10 | D6: Average efficiency gain | E6: =IF(E15=1, (((B9*'Team based gains'!B10)+(B10*'Team based gains'!B11)))/(B9+B10)*('Knapsack platform efficiency'!I32/'Knapsack platform efficiency'!I35), IF(E15=2, (((B9*'Team based gains'!B10)+(B10*'Team based gains'!B11)))/(B9+B10)*('Knapsack platform efficiency'!I33/'Knapsack platform efficiency'!I35), IF(E15=3, (((B9*'Team based gains'!B10)+(B10*'Team based gains'!B11)))/(B9+B10)*('Knapsack platform efficiency'!I34/'Knapsack platform efficiency'!I35), IF(E15=4, (((B9*'Team based gains'!B10)+(B10*'Team based gains'!B11)))/(B9+B10)*('Knapsack platform efficiency'!I35/'Knapsack platform efficiency'!I35), (((B9*'Team based gains'!B10)+(B10*'Team based gains'!B11)))/(B9+B10)*('Knapsack platform efficiency'!I36/'Knapsack platform efficiency'!I35) )))) -> 0.09 | G6: Estimated product teams per FTE | H6: =IF(E15=1, 'Knapsack platform efficiency'!E32, IF(AND(E15=2), 'Knapsack platform efficiency'!E33, IF(AND(E15=3), 'Knapsack platform efficiency'!E34, IF(AND(E15=4), 'Knapsack platform efficiency'!E35, IF(AND(E15=5), 'Knapsack platform efficiency'!E36, "error")) ))) -> 2.4 | J6: Bespoke DS | K6: =sum(E12) -> 0.82568807
G7: Infrastructure efficiency gain | H7: =sum((H6/E14)-1) -> 0.68 | J7: Knapsack (infra only) | K7: =sum(E8/H19) -> 1.387156 | M7: plus IPE | N7: =if(isnumber(K8), E8/Q24, "N/A") -> 16.985583
D8: Opportunity cost savings | E8: =sum(B13-E9) -> 766432.57 | G8: At current DS adoption rate | H8: =sum(H7*(E15/5)) -> 0.136 | J8: Improve to DS 2 | K8: =if(isnumber(M25), E8/M25, "N/A") -> 5.450929 | M8: plus IPE | N8: =if(isnumber(K8), E8/Q25, "N/A") -> 46.722249
A9: Total devs | B9: 50 | D9: Potential new load cost | E9: =sum(B13/(1+E6)) -> 8515917.4 | G9: Knapsack contract cost | H9: 150000 | J9: Improve to DS 3 | K9: =if(isnumber(M26), E8/M26, "N/A") -> 8.3651222 | M9: plus IPE | N9: =if(isnumber(Q25), E8/Q26, "N/A") -> 71.701047
A10: Total designers | B10: 20 | D10: Potential new product team avg cost | E10: =sum(E9/B6) -> 851591.74 | J10: Improve to DS 4 | K10: =if(isnumber(M27), E8/M27, "N/A") -> 11.279315 | M10: plus IPE | N10: =if(isnumber(Q27), E8/Q27, "N/A") -> 96.679846
A11: Averaged load cost | B11: =sum((((B9*'Team based gains'!B6)+(B10*'Team based gains'!B7))*'Team based gains'!B8)/(B9+B10)) -> 132605 | G11: Opportunity cost savings | H11: =sum(E9-H12) -> 1019511.2 | J11: Improve to DS 5 | K11: =if(isnumber(M28), E8/M28, "N/A") -> 14.193509 | M11: plus IPE | N11: =if(isnumber(Q28), E8/Q28, "N/A") -> 121.65865
D12: Savings to DS team cost multiplier | E12: =sum(E8/B24) -> 0.82568807 | G12: Potential new load cost | H12: =sum(E9/(1+H8)) -> 7496406.2
A13: Total load cost | B13: =sum(B11*(B9+B10)) -> 9282350 | G13: Potential new product team avg cost | H13: =sum(H12/B6) -> 749640.62
A14: Product team avg cost | B14: =sum(B13/B6) -> 928235 | D14: Product teams per FTE | E14: =sum(B6/(B20+B21)) -> 1.4285714
D15: DS Maturity | E15: =IF(E14<='Knapsack platform efficiency'!D32, 1, IF(AND(E14>'Knapsack platform efficiency'!D32, E14<='Knapsack platform efficiency'!D33), 2, IF(AND(E14>'Knapsack platform efficiency'!D33, E14<='Knapsack platform efficiency'!D34), 3,IF(AND(E14>'Knapsack platform efficiency'!D34, E14<='Knapsack platform efficiency'!D35), 4, 5)))) -> 1 | G15: ROI Multiplier (no Knapsack cost) | H15: =sum(E17*(1+H8)) -> 2.813945
A16: Expected return | B16: =sum(B13*B3) -> 27847050 | G16: True ROI (with Knapsack cost) | H16: =sum(H22/(B13+H9)) -> 2.7691956
D17: New ROI Multiplier | E17: =sum(B3*E12) -> 2.4770642
D18: Expected return (reduce prod costs) | E18: =sum(E9*E17) -> 21094474 | G18: DS $ per product team | H18: =sum((B22/H6)) -> 55252.083
A19: Design system team | D19: Expected return (same prod costs) | E19: =sum(B13*E17) -> 22992977 | G19: Total DS cost for same delivery | H19: =sum((B24*E14/H6)) -> 552520.83
A20: Total devs | B20: 5
A21: Total designers | B21: 2 | G21: Expected return (reduce prod costs) | H21: =sum(H12*H15) -> 21094474
A22: Averaged load cost | B22: =sum((((B20*'Team based gains'!B6)+(B21*'Team based gains'!B7))*'Team based gains'!B8)/(B20+B21)) -> 132605 | G22: Expected return (same prod costs) | H22: =sum(B13*H15) -> 26120022 | N22: WITH INTELLIGENT PRODUCT ENGINE
J23: Change DS team operational maturity (with Knapsack assist) | K23: Efficiency gain | L23: DS $ per product team | M23: Total DS cost for same delivery | N23: KS efficiency multiplier | P23: DS $ per product team | Q23: Total DS cost for same delivery | R23: KS Efficiency multiplier
A24: Total load cost | B24: =sum(B22*(B20+B21)) -> 928235 | J24: Already at baseline DS 1 | K24: N/A | L24: N/A | M24: N/A | N24: N/A | P24: =IF(E15=1, H18/(1+'Intelligent product engine'!D19), "N/A") -> 6446.0764 | Q24: =IF(ISNUMBER(P24), (B20+B21)*P24, "N/A") -> 45122.535 | R24: =IF(ISNUMBER(P24), B24/Q24, "N/A") -> 20.571429
A25: DS $ per product team | B25: =sum(B22/E14) -> 92823.5 | J25: Current to baseline DS 2 | K25: =IF((E15>=2), "N/A", ('Knapsack platform efficiency'!E33/(E14*H7))-1) -> 3.9411765 | L25: =IF(ISNUMBER(K25), B25/(H7+K25), "N/A") -> 20086.552 | M25: =IF(ISNUMBER(K25), (B20+B21)*L25, "N/A") -> 140605.86 | N25: =if(isnumber(M25), B24/M25, "N/A") -> 6.6016807 | P25: =IF(E15=2, H18/(1+'Intelligent product engine'!D19), IF(ISNUMBER(K25), L25/(1+'Intelligent product engine'!D19), "N/A")) -> 2343.431 | Q25: =IF(ISNUMBER(P25), (B20+B21)*P25, "N/A") -> 16404.017 | R25: =IF(ISNUMBER(P25), B24/Q25, "N/A") -> 56.585834
J26: Current to baseline DS 3 | K26: =IF((E15>=3), "N/A", ('Knapsack platform efficiency'!E34/(E14*H7))-1) -> 6.4117647 | L26: =IF(ISNUMBER(K26), B25/(H7+K26), "N/A") -> 13088.914 | M26: =IF(ISNUMBER(K26), (B20+B21)*L26, "N/A") -> 91622.4 | N26: =if(isnumber(M26), B24/M26, "N/A") -> 10.131092 | P26: =IF(E15=3, H18/(1+'Intelligent product engine'!D19), IF(ISNUMBER(K26), L26/(1+'Intelligent product engine'!D19), "N/A")) -> 1527.04 | Q26: =IF(ISNUMBER(P26), (B20+B21)*P26, "N/A") -> 10689.28 | R26: =IF(ISNUMBER(P26), B24/Q26, "N/A") -> 86.837935
A27: I'm a mid sized enterprise company with a growing suite of products | J27: Current to baseline DS 4 | K27: =IF((E15>=4), "N/A", ('Knapsack platform efficiency'!E35/(E14*H7))-1) -> 8.8823529 | L27: =IF(ISNUMBER(K27), B25/(H7+K27), "N/A") -> 9707.182 | M27: =IF(ISNUMBER(K27), (B20+B21)*L27, "N/A") -> 67950.274 | N27: =if(isnumber(M27), B24/M27, "N/A") -> 13.660504 | P27: =IF(E15=4, H18/(1+'Intelligent product engine'!D19), IF(ISNUMBER(K27), L27/(1+'Intelligent product engine'!D19), "N/A")) -> 1132.5046 | Q27: =IF(ISNUMBER(P27), (B20+B21)*P27, "N/A") -> 7927.5319 | R27: =IF(ISNUMBER(P27), B24/Q27, "N/A") -> 117.09004
A28: I spend this much each year delivering digital products | F28: =sum(B13) -> 9282350 | J28: Current to baseline DS 5 | K28: =IF((E15>=5), "N/A", ('Knapsack platform efficiency'!E36/(E14*H7))-1) -> 11.352941 | L28: =IF(ISNUMBER(K28), B25/(H7+K28), "N/A") -> 7714.1157 | M28: =IF(ISNUMBER(K28), (B20+B21)*L28, "N/A") -> 53998.81 | N28: =if(isnumber(M28), B24/M28, "N/A") -> 17.189916 | P28: =IF(E15=5, H18/(1+'Intelligent product engine'!D19), L28/(1+'Intelligent product engine'!D19)) -> 899.98016 | Q28: =IF(ISNUMBER(P28), (B20+B21)*P28, "N/A") -> 6299.8611 | R28: =IF(ISNUMBER(P28), B24/Q28, "N/A") -> 147.34214
A29: Then I build a design system team, and it costs me | F29: =sum(B24) -> 928235
A30: But it also saves me | F30: =sum(E8) -> 766432.57
A31: So the overall net balance is... | F31: =sum(F30-F29) -> -161802.43
A33: I engage Knapsack to be my design system platform
A34: The annual contract costs | F34: =sum(H9) -> 150000
A35: But now I can reduce my design system team costs by | F35: =sum(B24-H19) -> 375714.17
A36: Knapsack already saved me a net of | F36: =sum(F35-F34) -> 225714.17
A37: Knapsack also teach me how to improve how our design system works, which saves me an extra | F37: =sum(F35-M25) -> 235108.3
A38: So now they've saved me a net of | F38: =sum(F36:F37) -> 460822.47 | G38: (improve from DS1 to DS2)
A40: I decide to try out Knapsack's Intelligent Product Engine
A41: It's a bigger commitment, so the annual contract Knapsack contract is now | F41: =sum(F34*5) -> 750000
A43: And my delivery exponentially improved.
A44: I spend this much on product | F44: =sum(B13) -> 9282350
A45: I started by earning this in return | F45: =sum(F44*B3) -> 27847050
...

Sheet Bright Horizons
A1: Bright Horizons | B1: You can change a lot of the numbers, but the only ones you *have* to add are highlighted in green.
A3: COMPANY INFO | D3: DESIGN SYSTEM TEAM | G3: DESIGN SYSTEM TEAM EFFICIENCY GAINS | J3: GAINS OVER TIME (bespoke)
G4: Use baseline adoption rate? don't change for now! | H4: TRUE | J4: Months to next DS maturity | M4: 12
A5: Total staff | B5: 160 | D5: Design team maturity | E5: 2 | G5: Efficiency gain/user | H5: =if(E5=1, 'Design system reference'!B5, if(E5=2, 'Design system reference'!B6, if(E5=3, 'Design system reference'!B7, if(E5=4, 'Design system reference'!B8, 'Design system reference'!B9)))) -> 0.26373062
A6: Product staff | B6: 26.25 | D6: Total staff | E6: 4 | G6: Estimated adoption rate | H6: =if(H4=TRUE, if(E5=1, 'Design system reference'!D5, if(E5=2, 'Design system reference'!D6, if(E5=3, 'Design system reference'!D7, if(E5=4, 'Design system reference'!D8, if(E5=5, 'Design system reference'!D9, "N/A"))))), "N/A") -> 0.3 | J6: Month | K6: DS Improvement | L6: DS Maturity | M6: Adoption % | N6: Efficiency gain/user | O6: Org efficiency gain | P6: Efficiency gains $ | Q6: Net versus DS team cost | R6: Cumulative gain (bespoke)
A7: Developers | B7: 25 | D7: Developers | E7: =sum(E6-E8) -> 3 | G7: Manual adoption rate | H7: 0.01 | J7: 0 | K7: =sum(E5) -> 2 | L7: =min(5,(FLOOR(K7,1))) -> 2 | M7: =if($H$4=TRUE, if(L7=1, 'Design system reference'!$D$5, if(L7=2, 'Design system reference'!$D$6, if(L7=3, 'Design system reference'!$D$7, if(L7=4, 'Design system reference'!$D$8, if(L7=5, 'Design system reference'!$D$9, "N/A"))))), if(ISNUMBER(H7), H7, 0)) -> 0.3 | N7: =if(K7<2, 'Design system reference'!$B$5, IF(K7<3, 'Design system reference'!$B$6, IF(K7<4, 'Design system reference'!$B$7, IF(K7<5, 'Design system reference'!$B$8, 'Design system reference'!$B$9)))) -> 0.26373062 | O7: =sum(N7*M7) -> 0.079119187 | R7: 0
A8: Designers | B8: 1.25 | D8: Designers | E8: =if(E5=1, ROUNDDOWN(E6/(1+'Design system reference'!C5),0), if(E5=2, ROUNDDOWN(E6/(1+'Design system reference'!C6),0), if(E5=3, ROUNDDOWN(E6/(1+'Design system reference'!C7),0), if(E5=4, ROUNDDOWN(E6/(1+'Design system reference'!C8),0), if(E5=5, ROUNDDOWN(E6/(1+'Design system reference'!C9),0), FALSE ))))) -> 1 | G8: Org efficiency gain | H8: =if(isnumber(H7), H7*H5, H6*H5) -> 0.0026373063 | J8: 6 | K8: =if(K7=5,K7, SUM(K7+((1/$M$4)*(J8-J7)))) -> 2.5 | L8: =min(5,(FLOOR(K8,1))) -> 2 | M8: =if($H$4=TRUE, if(L8=1, 'Design system reference'!$D$5, if(L8=2, 'Design system reference'!$D$6, if(L8=3, 'Design system reference'!$D$7, if(L8=4, 'Design system reference'!$D$8, if(L8=5, 'Design system reference'!$D$9, "N/A"))))), if(ISNUMBER(H8), H8, 0)) -> 0.3 | N8: =if(K8<2, 'Design system reference'!$B$5, IF(K8<3, 'Design system reference'!$B$6, IF(K8<4, 'Design system reference'!$B$7, IF(K8<5, 'Design system reference'!$B$8, 'Design system reference'!$B$9)))) -> 0.26373062 | O8: =sum(N8*M8) -> 0.079119187 | P8: =sum(($B$20*O8)*0.5) -> 298113.88 | Q8: =sum(P8-$E$11) -> -708397.34 | R8: =sum(R7+Q8) -> -708397.34
A9: # of product teams (rounded) | B9: 6 | J9: 12 | K9: =if(K8=5,K8, SUM(K8+((1/$M$4)*(J9-J8)))) -> 3 | L9: =min(5,(FLOOR(K9,1))) -> 3 | M9: =if($H$4=TRUE, if(L9=1, 'Design system reference'!$D$5, if(L9=2, 'Design system reference'!$D$6, if(L9=3, 'Design system reference'!$D$7, if(L9=4, 'Design system reference'!$D$8, if(L9=5, 'Design system reference'!$D$9, "N/A"))))), if(ISNUMBER(H9), H9, 0)) -> 0.5 | N9: =if(K9<2, 'Design system reference'!$B$5, IF(K9<3, 'Design system reference'!$B$6, IF(K9<4, 'Design system reference'!$B$7, IF(K9<5, 'Design system reference'!$B$8, 'Design system reference'!$B$9)))) -> 0.461875 | O9: =sum(N9*M9) -> 0.2309375 | P9: =sum(($B$20*O9)*0.5) -> 870151.43 | Q9: =sum(P9-$E$11) -> -136359.79 | R9: =sum(R8+Q9) -> -844757.13
D10: Design team load cost | E10: =sum((((B11*E7)+(B12*E8))/E6)*B13) -> 251627.8 | G10: Efficiency gains $ | H10: =sum(B20*H8) -> 19874.259 | J10: 18 | K10: =if(K9=5,K9, SUM(K9+((1/$M$4)*(J10-J9)))) -> 3.5 | L10: =min(5,(FLOOR(K10,1))) -> 3 | M10: =if($H$4=TRUE, if(L10=1, 'Design system reference'!$D$5, if(L10=2, 'Design system reference'!$D$6, if(L10=3, 'Design system reference'!$D$7, if(L10=4, 'Design system reference'!$D$8, if(L10=5, 'Design system reference'!$D$9, "N/A"))))), if(ISNUMBER(H10), H10, 0)) -> 0.5 | N10: =if(K10<2, 'Design system reference'!$B$5, IF(K10<3, 'Design system reference'!$B$6, IF(K10<4, 'Design system reference'!$B$7, IF(K10<5, 'Design system reference'!$B$8, 'Design system reference'!$B$9)))) -> 0.461875 | O10: =sum(N10*M10) -> 0.2309375 | P10: =sum(($B$20*O10)*0.5) -> 870151.43 | Q10: =sum(P10-$E$11) -> -136359.79 | R10: =sum(R9+Q10) -> -981116.93
A11: Developer avg salary | B11: 208000 | C11: data provided by Kelley | D11: Design team total cost | E11: =sum(E10*E6) -> 1006511.2 | G11: Net versus DS team cost | H11: =sum(H10-E11) -> -986636.96 | J11: 24 | K11: =if(K10=5,K10, SUM(K10+((1/$M$4)*(J11-J10)))) -> 4 | L11: =min(5,(FLOOR(K11,1))) -> 4 | M11: =if($H$4=TRUE, if(L11=1, 'Design system reference'!$D$5, if(L11=2, 'Design system reference'!$D$6, if(L11=3, 'Design system reference'!$D$7, if(L11=4, 'Design system reference'!$D$8, if(L11=5, 'Design system reference'!$D$9, "N/A"))))), if(ISNUMBER(H11), H11, 0)) -> 0.8 | N11: =if(K11<2, 'Design system reference'!$B$5, IF(K11<3, 'Design system reference'!$B$6, IF(K11<4, 'Design system reference'!$B$7, IF(K11<5, 'Design system reference'!$B$8, 'Design system reference'!$B$9)))) -> 0.59397125 | O11: =sum(N11*M11) -> 0.475177 | P11: =sum(($B$20*O11)*0.5) -> 1790423.6 | Q11: =sum(P11-$E$11) -> 783912.36 | R11: =sum(R10+Q11) -> -197204.57
A12: Designer avg salary | B12: =sum('Other references'!B9) -> 79854 | C12: data provide by Glassdoor | J12: 30 | K12: =if(K11=5,K11, SUM(K11+((1/$M$4)*(J12-J11)))) -> 4.5 | L12: =min(5,(FLOOR(K12,1))) -> 4 | M12: =if($H$4=TRUE, if(L12=1, 'Design system reference'!$D$5, if(L12=2, 'Design system reference'!$D$6, if(L12=3, 'Design system reference'!$D$7, if(L12=4, 'Design system reference'!$D$8, if(L12=5, 'Design system reference'!$D$9, "N/A"))))), if(ISNUMBER(H12), H12, 0)) -> 0.8 | N12: =if(K12<2, 'Design system reference'!$B$5, IF(K12<3, 'Design system reference'!$B$6, IF(K12<4, 'Design system reference'!$B$7, IF(K12<5, 'Design system reference'!$B$8, 'Design system reference'!$B$9)))) -> 0.59397125 | O12: =sum(N12*M12) -> 0.475177 | P12: =sum(($B$20*O12)*0.5) -> 1790423.6 | Q12: =sum(P12-$E$11) -> 783912.36 | R12: =sum(R11+Q12) -> 586707.79
A13: Load cost multiplier | B13: =sum('Other references'!B10) -> 1.43 | J13: 36 | K13: =if(K12=5,K12, SUM(K12+((1/$M$4)*(J13-J12)))) -> 5 | L13: =min(5,(FLOOR(K13,1))) -> 5 | M13: =if($H$4=TRUE, if(L13=1, 'Design system reference'!$D$5, if(L13=2, 'Design system reference'!$D$6, if(L13=3, 'Design system reference'!$D$7, if(L13=4, 'Design system reference'!$D$8, if(L13=5, 'Design system reference'!$D$9, "N/A"))))), if(ISNUMBER(H19), H19, 0)) -> 0.95 | N13: =if(K13<2, 'Design system reference'!$B$5, IF(K13<3, 'Design system reference'!$B$6, IF(K13<4, 'Design system reference'!$B$7, IF(K13<5, 'Design system reference'!$B$8, 'Design system reference'!$B$9)))) -> 0.66001937 | O13: =sum(N13*M13) -> 0.62701841 | P13: =sum(($B$20*O13)*0.5) -> 2362548.1 | Q13: =sum(P13-$E$11) -> 1356036.9 | R13: =sum(R12+Q13) -> 1942744.7
J14: 42 | K14: =if(K13=5,K13, SUM(K13+((1/$M$4)*(J14-J13)))) -> 5 | L14: =min(5,(FLOOR(K14,1))) -> 5 | M14: =if($H$4=TRUE, if(L14=1, 'Design system reference'!$D$5, if(L14=2, 'Design system reference'!$D$6, if(L14=3, 'Design system reference'!$D$7, if(L14=4, 'Design system reference'!$D$8, if(L14=5, 'Design system reference'!$D$9, "N/A"))))), if(ISNUMBER(H20), H20, 0)) -> 0.95 | N14: =if(K14<2, 'Design system reference'!$B$5, IF(K14<3, 'Design system reference'!$B$6, IF(K14<4, 'Design system reference'!$B$7, IF(K14<5, 'Design system reference'!$B$8, 'Design system reference'!$B$9)))) -> 0.66001937 | O14: =sum(N14*M14) -> 0.62701841 | P14: =sum(($B$20*O14)*0.5) -> 2362548.1 | Q14: =sum(P14-$E$11) -> 1356036.9 | R14: =sum(R13+Q14) -> 3298781.6
A15: Developer load cost | B15: =sum(B11*B13) -> 297440 | J15: 48 | K15: =if(K14=5,K14, SUM(K14+((1/$M$4)*(J15-J14)))) -> 5 | L15: =min(5,(FLOOR(K15,1))) -> 5 | M15: =if($H$4=TRUE, if(L15=1, 'Design system reference'!$D$5, if(L15=2, 'Design system reference'!$D$6, if(L15=3, 'Design system reference'!$D$7, if(L15=4, 'Design system reference'!$D$8, if(L15=5, 'Design system reference'!$D$9, "N/A"))))), if(ISNUMBER(H21), H21, 0)) -> 0.95 | N15: =if(K15<2, 'Design system reference'!$B$5, IF(K15<3, 'Design system reference'!$B$6, IF(K15<4, 'Design system reference'!$B$7, IF(K15<5, 'Design system reference'!$B$8, 'Design system reference'!$B$9)))) -> 0.66001937 | O15: =sum(N15*M15) -> 0.62701841 | P15: =sum(($B$20*O15)*0.5) -> 2362548.1 | Q15: =sum(P15-$E$11) -> 1356036.9 | R15: =sum(R14+Q15) -> 4654818.5
A16: Designer load cost | B16: =sum(B12*B13) -> 114191.22 | J16: 54 | K16: =if(K15=5,K15, SUM(K15+((1/$M$4)*(J16-J15)))) -> 5 | L16: =min(5,(FLOOR(K16,1))) -> 5 | M16: =if($H$4=TRUE, if(L16=1, 'Design system reference'!$D$5, if(L16=2, 'Design system reference'!$D$6, if(L16=3, 'Design system reference'!$D$7, if(L16=4, 'Design system reference'!$D$8, if(L16=5, 'Design system reference'!$D$9, "N/A"))))), if(ISNUMBER(H22), H22, 0)) -> 0.95 | N16: =if(K16<2, 'Design system reference'!$B$5, IF(K16<3, 'Design system reference'!$B$6, IF(K16<4, 'Design system reference'!$B$7, IF(K16<5, 'Design system reference'!$B$8, 'Design system reference'!$B$9)))) -> 0.66001937 | O16: =sum(N16*M16) -> 0.62701841 | P16: =sum(($B$20*O16)*0.5) -> 2362548.1 | Q16: =sum(P16-$E$11) -> 1356036.9 | R16: =sum(R15+Q16) -> 6010855.5
J17: 60 | K17: =if(K16=5,K16, SUM(K16+((1/$M$4)*(J17-J16)))) -> 5 | L17: =min(5,(FLOOR(K17,1))) -> 5 | M17: =if($H$4=TRUE, if(L17=1, 'Design system reference'!$D$5, if(L17=2, 'Design system reference'!$D$6, if(L17=3, 'Design system reference'!$D$7, if(L17=4, 'Design system reference'!$D$8, if(L17=5, 'Design system reference'!$D$9, "N/A"))))), if(ISNUMBER(H17), H17, 0)) -> 0.95 | N17: =if(K17<2, 'Design system reference'!$B$5, IF(K17<3, 'Design system reference'!$B$6, IF(K17<4, 'Design system reference'!$B$7, IF(K17<5, 'Design system reference'!$B$8, 'Design system reference'!$B$9)))) -> 0.66001937 | O17: =sum(N17*M17) -> 0.62701841 | P17: =sum(($B$20*O17)*0.5) -> 2362548.1 | Q17: =sum(P17-$E$11) -> 1356036.9 | R17: =sum(R16+Q17) -> 7366892.4
A18: Prod team load cost | B18: =sum(((B15*B7)+(B12*B8))/B6) -> 287078.76
G19: KNAPSACK OPERATIONAL EFFICIENCY GAINS | J19: GAINS OVER TIME (Knapsack)
A20: Baseline product spend | B20: =sum(B18*B6) -> 7535817.5 | G20: Flat rate | J20: Months to next DS maturity | M20: DS1-2, DS2-3 | N20: 6 | P20: DS3-4, DS4-5 | Q20: 9
G21: Annual contract cost | H21: 75000
A22: ROI on product spend | B22: 3 | G22: Net reduction in DS team cost | H22: =sum((E11*'Knapsack reference'!B3)-H21) -> 75976.683 | J22: Month | K22: DS Improvement | L22: DS Maturity | M22: Adoption % | N22: Efficiency gain/user | O22: Org efficiency gain | P22: Efficiency gains $ | Q22: Net versus DS team cost | R22: Cumulative gain (Knapsack) | S22: Differential | T22: KS efficiency gain to product spend | V22: ROI on product spend
J23: 0 | K23: =sum(E5) -> 2 | L23: =floor(K23,1) -> 2 | M23: =if($H$4=TRUE, if(L23=1, 'Design system reference'!D$5, if(L23=2, 'Design system reference'!D$6, if(L23=3, 'Design system reference'!D$7, if(L23=4, 'Design system reference'!D$8, if(L23=5, 'Design system reference'!D$9, "N/A"))))), if(ISNUMBER($H$7), $H$7, 0)) -> 0.3 | N23: =if(L23<2, 'Design system reference'!$B$5, IF(L23<3, 'Design system reference'!$B$6, IF(L23<4, 'Design system reference'!$B$7, IF(L23<5, 'Design system reference'!$B$8, 'Design system reference'!$B$9)))) -> 0.26373062 | O23: =sum(N23*M23) -> 0.079119187 | R23: 0 | V23: =sum($B$22) -> 3
A24: Revenue | B24: =sum(B20*B22) -> 22607452 | J24: 6 | K24: =if(K23=5,K23, IF(K23<3, SUM(K23+((1/$N$20)*(J24-J23))), IF(K23>=3, SUM(K23+((1/$Q$20)*(J24-J23)))))) -> 3 | L24: =floor(K24,1) -> 3 | M24: =if($H$4=TRUE, if(L24=1, 'Design system reference'!D$5, if(L24=2, 'Design system reference'!D$6, if(L24=3, 'Design system reference'!D$7, if(L24=4, 'Design system reference'!D$8, if(L24=5, 'Design system reference'!D$9, "N/A"))))), if(ISNUMBER($H$7), $H$7, 0)) -> 0.5 | N24: =if(L24<2, 'Design system reference'!$B$5, IF(L24<3, 'Design system reference'!$B$6, IF(L24<4, 'Design system reference'!$B$7, IF(L24<5, 'Design system reference'!$B$8, 'Design system reference'!$B$9)))) -> 0.461875 | O24: =sum(N24*M24) -> 0.2309375 | P24: =sum(($B$20*O24)*0.5) -> 870151.43 | Q24: =sum(P24-$E$11+$H$22) -> -60383.11 | R24: =sum(R23+Q24) -> -60383.11 | S24: =sum(R24-R8) -> 648014.23 | T24: =sum(S24/B20) -> 0.085991232 | V24: =sum($B$22*(1+T24)) -> 3.2579737
J25: 12 | K25: =if(K24=5,K24, IF(K24<3, SUM(K24+((1/$N$20)*(J25-J24))), IF(K24>=3, SUM(K24+((1/$Q$20)*(J25-J24)))))) -> 3.6666667 | L25: =floor(K25,1) -> 3 | M25: =if($H$4=TRUE, if(L25=1, 'Design system reference'!D$5, if(L25=2, 'Design system reference'!D$6, if(L25=3, 'Design system reference'!D$7, if(L25=4, 'Design system reference'!D$8, if(L25=5, 'Design system reference'!D$9, "N/A"))))), if(ISNUMBER($H$7), $H$7, 0)) -> 0.5 | N25: =if(L25<2, 'Design system reference'!$B$5, IF(L25<3, 'Design system reference'!$B$6, IF(L25<4, 'Design system reference'!$B$7, IF(L25<5, 'Design system reference'!$B$8, 'Design system reference'!$B$9)))) -> 0.461875 | O25: =sum(N25*M25) -> 0.2309375 | P25: =sum(($B$20*O25)*0.5) -> 870151.43 | Q25: =sum(P25-$E$11+$H$22) -> -60383.11 | R25: =sum(R24+Q25) -> -120766.22 | S25: =sum(R25-R9) -> 723990.91 | T25: =sum(S25/$B$20) -> 0.096073308 | V25: =sum($B$22*(1+T25)) -> 3.2882199
J26: 18 | K26: =if(K25=5,K25, IF(K25<3, SUM(K25+((1/$N$20)*(J26-J25))), IF(K25>=3, SUM(K25+((1/$Q$20)*(J26-J25)))))) -> 4.3333333 | L26: =MIN(5,(floor(K26,1))) -> 4 | M26: =if($H$4=TRUE, if(L26=1, 'Design system reference'!D$5, if(L26=2, 'Design system reference'!D$6, if(L26=3, 'Design system reference'!D$7, if(L26=4, 'Design system reference'!D$8, if(L26=5, 'Design system reference'!D$9, "N/A"))))), if(ISNUMBER($H$7), $H$7, 0)) -> 0.8 | N26: =if(L26<2, 'Design system reference'!$B$5, IF(L26<3, 'Design system reference'!$B$6, IF(L26<4, 'Design system reference'!$B$7, IF(L26<5, 'Design system reference'!$B$8, 'Design system reference'!$B$9)))) -> 0.59397125 | O26: =sum(N26*M26) -> 0.475177 | P26: =sum(($B$20*O26)*0.5) -> 1790423.6 | Q26: =sum(P26-$E$11+$H$22) -> 859889.04 | R26: =sum(R25+Q26) -> 739122.82 | S26: =sum(R26-R10) -> 1720239.7 | T26: =sum(S26/$B$20) -> 0.22827513 | V26: =sum($B$22*(1+T26)) -> 3.6848254
J27: 24 | K27: =if(K26=5,K26, IF(K26<3, SUM(K26+((1/$N$20)*(J27-J26))), IF(K26>=3, SUM(K26+((1/$Q$20)*(J27-J26)))))) -> 5 | L27: =MIN(5,(floor(K27,1))) -> 5 | M27: =if($H$4=TRUE, if(L27=1, 'Design system reference'!D$5, if(L27=2, 'Design system reference'!D$6, if(L27=3, 'Design system reference'!D$7, if(L27=4, 'Design system reference'!D$8, if(L27=5, 'Design system reference'!D$9, "N/A"))))), if(ISNUMBER($H$7), $H$7, 0)) -> 0.95 | N27: =if(L27<2, 'Design system reference'!$B$5, IF(L27<3, 'Design system reference'!$B$6, IF(L27<4, 'Design system reference'!$B$7, IF(L27<5, 'Design system reference'!$B$8, 'Design system reference'!$B$9)))) -> 0.66001937 | O27: =sum(N27*M27) -> 0.62701841 | P27: =sum(($B$20*O27)*0.5) -> 2362548.1 | Q27: =sum(P27-$E$11+$H$22) -> 1432013.6 | R27: =sum(R26+Q27) -> 2171136.4 | S27: =sum(R27-R11) -> 2368341 | T27: =sum(S27/$B$20) -> 0.31427791 | V27: =sum($B$22*(1+T27)) -> 3.9428337
J28: 30 | K28: =if(K27=5,K27, IF(K27<3, SUM(K27+((1/$N$20)*(J28-J27))), IF(K27>=3, SUM(K27+((1/$Q$20)*(J28-J27)))))) -> 5 | L28: =MIN(5,(floor(K28,1))) -> 5 | M28: =if($H$4=TRUE, if(L28=1, 'Design system reference'!D$5, if(L28=2, 'Design system reference'!D$6, if(L28=3, 'Design system reference'!D$7, if(L28=4, 'Design system reference'!D$8, if(L28=5, 'Design system reference'!D$9, "N/A"))))), if(ISNUMBER($H$7), $H$7, 0)) -> 0.95 | N28: =if(L28<2, 'Design system reference'!$B$5, IF(L28<3, 'Design system reference'!$B$6, IF(L28<4, 'Design system reference'!$B$7, IF(L28<5, 'Design system reference'!$B$8, 'Design system reference'!$B$9)))) -> 0.66001937 | O28: =sum(N28*M28) -> 0.62701841 | P28: =sum(($B$20*O28)*0.5) -> 2362548.1 | Q28: =sum(P28-$E$11+$H$22) -> 1432013.6 | R28: =sum(R27+Q28) -> 3603150 | S28: =sum(R28-R12) -> 3016442.2 | T28: =sum(S28/$B$20) -> 0.40028069 | V28: =sum($B$22*(1+T28)) -> 4.2008421
J29: 36 | K29: =if(K28=5,K28, IF(K28<3, SUM(K28+((1/$N$20)*(J29-J28))), IF(K28>=3, SUM(K28+((1/$Q$20)*(J29-J28)))))) -> 5 | L29: =MIN(5,(floor(K29,1))) -> 5 | M29: =if($H$4=TRUE, if(L29=1, 'Design system reference'!D$5, if(L29=2, 'Design system reference'!D$6, if(L29=3, 'Design system reference'!D$7, if(L29=4, 'Design system reference'!D$8, if(L29=5, 'Design system reference'!D$9, "N/A"))))), if(ISNUMBER($H$7), $H$7, 0)) -> 0.95 | N29: =if(L29<2, 'Design system reference'!$B$5, IF(L29<3, 'Design system reference'!$B$6, IF(L29<4, 'Design system reference'!$B$7, IF(L29<5, 'Design system reference'!$B$8, 'Design system reference'!$B$9)))) -> 0.66001937 | O29: =sum(N29*M29) -> 0.62701841 | P29: =sum(($B$20*O29)*0.5) -> 2362548.1 | Q29: =sum(P29-$E$11+$H$22) -> 1432013.6 | R29: =sum(R28+Q29) -> 5035163.6 | S29: =sum(R29-R13) -> 3092418.9 | T29: =sum(S29/$B$20) -> 0.41036277 | V29: =sum($B$22*(1+T29)) -> 4.2310883
J30: 42 | K30: =if(K29=5,K29, IF(K29<3, SUM(K29+((1/$N$20)*(J30-J29))), IF(K29>=3, SUM(K29+((1/$Q$20)*(J30-J29)))))) -> 5 | L30: =MIN(5,(floor(K30,1))) -> 5 | M30: =if($H$4=TRUE, if(L30=1, 'Design system reference'!D$5, if(L30=2, 'Design system reference'!D$6, if(L30=3, 'Design system reference'!D$7, if(L30=4, 'Design system reference'!D$8, if(L30=5, 'Design system reference'!D$9, "N/A"))))), if(ISNUMBER($H$7), $H$7, 0)) -> 0.95 | N30: =if(L30<2, 'Design system reference'!$B$5, IF(L30<3, 'Design system reference'!$B$6, IF(L30<4, 'Design system reference'!$B$7, IF(L30<5, 'Design system reference'!$B$8, 'Design system reference'!$B$9)))) -> 0.66001937 | O30: =sum(N30*M30) -> 0.62701841 | P30: =sum(($B$20*O30)*0.5) -> 2362548.1 | Q30: =sum(P30-$E$11+$H$22) -> 1432013.6 | R30: =sum(R29+Q30) -> 6467177.2 | S30: =sum(R30-R14) -> 3168395.6 | T30: =sum(S30/$B$20) -> 0.42044484 | V30: =sum($B$22*(1+T30)) -> 4.2613345
J31: 48 | K31: =if(K30=5,K30, IF(K30<3, SUM(K30+((1/$N$20)*(J31-J30))), IF(K30>=3, SUM(K30+((1/$Q$20)*(J31-J30)))))) -> 5 | L31: =MIN(5,(floor(K31,1))) -> 5 | M31: =if($H$4=TRUE, if(L31=1, 'Design system reference'!D$5, if(L31=2, 'Design system reference'!D$6, if(L31=3, 'Design system reference'!D$7, if(L31=4, 'Design system reference'!D$8, if(L31=5, 'Design system reference'!D$9, "N/A"))))), if(ISNUMBER($H$7), $H$7, 0)) -> 0.95 | N31: =if(L31<2, 'Design system reference'!$B$5, IF(L31<3, 'Design system reference'!$B$6, IF(L31<4, 'Design system reference'!$B$7, IF(L31<5, 'Design system reference'!$B$8, 'Design system reference'!$B$9)))) -> 0.66001937 | O31: =sum(N31*M31) -> 0.62701841 | P31: =sum(($B$20*O31)*0.5) -> 2362548.1 | Q31: =sum(P31-$E$11+$H$22) -> 1432013.6 | R31: =sum(R30+Q31) -> 7899190.8 | S31: =sum(R31-R15) -> 3244372.3 | T31: =sum(S31/$B$20) -> 0.43052692 | V31: =sum($B$22*(1+T31)) -> 4.2915808
J32: 54 | K32: =if(K31=5,K31, IF(K31<3, SUM(K31+((1/$N$20)*(J32-J31))), IF(K31>=3, SUM(K31+((1/$Q$20)*(J32-J31)))))) -> 5 | L32: =MIN(5,(floor(K32,1))) -> 5 | M32: =if($H$4=TRUE, if(L32=1, 'Design system reference'!D$5, if(L32=2, 'Design system reference'!D$6, if(L32=3, 'Design system reference'!D$7, if(L32=4, 'Design system reference'!D$8, if(L32=5, 'Design system reference'!D$9, "N/A"))))), if(ISNUMBER($H$7), $H$7, 0)) -> 0.95 | N32: =if(L32<2, 'Design system reference'!$B$5, IF(L32<3, 'Design system reference'!$B$6, IF(L32<4, 'Design system reference'!$B$7, IF(L32<5, 'Design system reference'!$B$8, 'Design system reference'!$B$9)))) -> 0.66001937 | O32: =sum(N32*M32) -> 0.62701841 | P32: =sum(($B$20*O32)*0.5) -> 2362548.1 | Q32: =sum(P32-$E$11+$H$22) -> 1432013.6 | R32: =sum(R31+Q32) -> 9331204.4 | S32: =sum(R32-R16) -> 3320349 | T32: =sum(S32/$B$20) -> 0.44060899 | V32: =sum($B$22*(1+T32)) -> 4.321827
J33: 60 | K33: =if(K32=5,K32, IF(K32<3, SUM(K32+((1/$N$20)*(J33-J32))), IF(K32>=3, SUM(K32+((1/$Q$20)*(J33-J32)))))) -> 5 | L33: =MIN(5,(floor(K33,1))) -> 5 | M33: =if($H$4=TRUE, if(L33=1, 'Design system reference'!D$5, if(L33=2, 'Design system reference'!D$6, if(L33=3, 'Design system reference'!D$7, if(L33=4, 'Design system reference'!D$8, if(L33=5, 'Design system reference'!D$9, "N/A"))))), if(ISNUMBER($H$7), $H$7, 0)) -> 0.95 | N33: =if(L33<2, 'Design system reference'!$B$5, IF(L33<3, 'Design system reference'!$B$6, IF(L33<4, 'Design system reference'!$B$7, IF(L33<5, 'Design system reference'!$B$8, 'Design system reference'!$B$9)))) -> 0.66001937 | O33: =sum(N33*M33) -> 0.62701841 | P33: =sum(($B$20*O33)*0.5) -> 2362548.1 | Q33: =sum(P33-$E$11+$H$22) -> 1432013.6 | R33: =sum(R32+Q33) -> 10763218 | S33: =sum(R33-R17) -> 3396325.7 | T33: =sum(S33/$B$20) -> 0.45069107 | V33: =sum($B$22*(1+T33)) -> 4.3520732
G35: KNAPSACK INTELLIGENT PRODUCT ENGINE | J35: PRODUCTIVITY OVER TIME | Q35: With bespoke DS
J36: Month | L36: New ROI | M36: Half year value of value of product spend | N36: Cumulative (Knapsack IPE) | O36: Potential annual value of product spend | P36: Each $ on Knapsack is worth... | Q36: Value of product spend | R36: Cumulative (Canvas + DS)
G37: Efficiency improvement | H37: =sum('Knapsack reference'!D33) -> 12 | J37: 0 | N37: 0 | R37: 0
G38: Annual contract cost | H38: =sum(H21*5) -> 375000 | J38: 6 | L38: =sum($H$37*V24) -> 39.095684 | M38: =sum(($B$20*L38)*0.5) -> 1.4730897e+08 | N38: =sum(N37+M38) -> 1.4730897e+08 | Q38: =sum($B$24) -> 22607452 | R38: =sum(R37+Q38) -> 22607452
J39: 12 | L39: =sum($H$37*V25) -> 39.458639 | M39: =sum(($B$20*L39)*0.5) -> 1.4867655e+08 | N39: =sum(N38+M39) -> 2.9598552e+08 | O39: =sum(M38+M39) -> 2.9598552e+08 | P39: =sum((O39-$B$24)/$H$38) -> 729.00819 | Q39: =sum($B$24) -> 22607452 | R39: =sum(R38+Q39) -> 45214905
G40: Turn quarterly release cycles into weekly ones | J40: 18 | L40: =sum($H$37*V26) -> 44.217905 | M40: =sum(($B$20*L40)*0.5) -> 1.6660903e+08 | N40: =sum(N39+M40) -> 462594553 | Q40: =sum($B$24) -> 22607452 | R40: =sum(R39+Q40) -> 67822358
J41: 24 | L41: =sum($H$37*V27) -> 47.314005 | M41: =sum(($B$20*L41)*0.5) -> 1.7827485e+08 | N41: =sum(N40+M41) -> 6.4086941e+08 | O41: =sum(M40+M41) -> 3.4488388e+08 | P41: =sum((O41-$B$24)/$H$38) -> 859.40382 | Q41: =sum($B$24) -> 22607452 | R41: =sum(R40+Q41) -> 90429810
J42: 30 | L42: =sum($H$37*V28) -> 50.410105 | M42: =sum(($B$20*L42)*0.5) -> 1.8994068e+08 | N42: =sum(N41+M42) -> 8.3081008e+08 | Q42: =sum($B$24) -> 22607452 | R42: =sum(R41+Q42) -> 1.1303726e+08
...

Sheet Efficiency Gains with Investmen

Sheet Value of Product Spend with AIM

Sheet Design system reference
F2: Example org efficiency gain at adoption rate
B3: Efficiency gain/user | C3: Dev:Design Ratio | D3: Estimate baseline adoption | F3: 0.2 | G3: 0.4 | H3: 0.6 | I3: 0.8 | J3: 1
A5: Design system maturity 1 | B5: =sum(B7*0.286) -> 0.13209625 | C5: 4 | D5: 0.1 | F5: =sum(F3*B5) -> 0.02641925 | G5: =sum(G3*B5) -> 0.0528385 | H5: =sum(H3*B5) -> 0.07925775 | I5: =sum(I3*B5) -> 0.105677 | J5: =sum(J3*B5) -> 0.13209625
A6: Design system maturity 2 | B6: =sum(B7*0.571) -> 0.26373062 | C6: 3 | D6: 0.3 | F6: =sum(F3*B6) -> 0.052746125 | G6: =sum(G3*B6) -> 0.10549225 | H6: =sum(H3*B6) -> 0.15823837 | I6: =sum(I3*B6) -> 0.2109845 | J6: =sum(J3*B6) -> 0.26373062
A7: Design system maturity 3 | B7: =sum(((B11*'Other references'!B3*10)+(B12*'Other references'!B4*10))/10) -> 0.461875 | C7: 2 | D7: 0.5 | F7: =sum(F3*B7) -> 0.092375 | G7: =sum(G3*B7) -> 0.18475 | H7: =sum(H3*B7) -> 0.277125 | I7: =sum(I3*B7) -> 0.3695 | J7: =sum(J3*B7) -> 0.461875
A8: Design system maturity 4 | B8: =sum(B7*1.286) -> 0.59397125 | C8: 1.5 | D8: 0.8 | F8: =sum(F3*B8) -> 0.11879425 | G8: =sum(G3*B8) -> 0.2375885 | H8: =sum(H3*B8) -> 0.35638275 | I8: =sum(I3*B8) -> 0.475177 | J8: =sum(J3*B8) -> 0.59397125
A9: Design system maturity 5 | B9: =sum(B7*1.429) -> 0.66001937 | C9: 1 | D9: 0.95 | F9: =sum(F3*B9) -> 0.13200387 | G9: =sum(G3*B9) -> 0.26400775 | H9: =sum(H3*B9) -> 0.39601162 | I9: =sum(I3*B9) -> 0.5280155 | J9: =sum(J3*B9) -> 0.66001937
A11: Developer efficiency gain from design system | B11: =sum(38%/0.8) -> 0.475 | C11: Source: Smashing Magazine, with adjustment that their calculations assume a baseline adoption of 80%
A12: Designer efficiency gain from design system | B12: =sum(31%/0.8) -> 0.3875 | C12: Source: Smashing Magazine, with adjustment that their calculations assume a baseline adoption of 80%
A14: Design system maturity | B14: Name | C14: Description
A15: 1 | B15: Fragmented / Ad Hoc | C15: No consistent system usage; duplicative tools, reactive work
A16: 2 | B16: Documented but Manual | C16: Has guidance, but no enforcement; Figma-to-code handoff still dominant
A17: 3 | B17: Governed & Adopted | C17: Design system is enforced, broadly adopted; teams align to DS patterns
A18: 4 | B18: Integrated into Delivery | C18: System is part of CI/CD, components tokenized, teams onboarded consistently
A19: 5 | B19: Orchestrated / Optimized | C19: Governance + delivery model is intelligent, integrated, and scalable

Sheet Knapsack reference
A2: Benefit | B2: Value | C2: Notes
A3: Design system team overhead savings | B3: 0.15 | C3: Opportunity cost from reduced operational costs, applies to 100% of DS team cost, reflecting infrastructure, tooling consolidation, reduced management needs, etc.
A4: Average annual contract cost (platform + basic proserv) | B4: 150000
A5: Average annual contract cost (IPE) | B5: =sum(B4*5) -> 750000
A7: KNAPSACK PROCESS AND PROSERV IMPACT ON ORGANIZATIONAL DESIGN SYSTEM MATURITY
A8: Operational maturity | B8: Months w/o Knapsack | C8: Months w/ Knapsack | D8: Months Saved | E8: % Impact
A9: DS1 → DS2 | B9: 12 | C9: 6 | D9: 6 | E9: =sum(D9/B9) -> 0.5
A10: DS2 → DS3 | B10: 12 | C10: 6 | D10: 6 | E10: =sum(D10/B10) -> 0.5
A11: DS3 → DS4 | B11: 12 | C11: 8 | D11: 4 | E11: =sum(D11/B11) -> 0.33333333
A12: DS4 → DS5 | B12: 12 | C12: 10 | D12: 2 | E12: =sum(D12/B12) -> 0.16666667
A14: INTELLIGENT PRODUCT ENGINE
A15: Dimension | B15: Traditional Design System (Canvas-led) | C15: Knapsack Intelligent Product Engine
A16: Starting Point | B16: Design happens in a canvas (Figma, etc.) | C16: Existing product artifacts are ingested into structured models
A17: Design/Dev Handoff | B17: Relies on mockups passed to developers | C17: Skipped entirely — composition happens in or near code
A18: System Governance | B18: Manual, reference-based governance enforcement | C18: Embedded in the MCP and applied through validation + rules
A19: Component Composition | B19: Manual implementation by engineers from design specs | C19: AI-assisted composition assistant uses tokens, components, and patterns
A20: Cycle Time | B20: Long — design, spec, review, dev, re-review | C20: Short — assisted, structured generation with shared context
A21: Version 1 Output | B21: Coded manually by dev team after back-and-forth iteration | C21: First version generated rapidly with contextual design system knowledge
A22: Release Path | B22: Multi-step refinement → eventual release | C22: V1 product is reviewed, optionally refined, then released
A23: Efficiency Scaling | B23: High headcount required for alignment, documentation, ops | C23: Low headcount needed — alignment and documentation are emergent
A24: Tooling Footprint | B24: Disconnected tools: Figma, Storybook, Confluence, internal wikis | C24: Unified via Knapsack MCP + agent ecosystem
A25: Governance Model | B25: Reference governance: “Did you follow the design system?” | C25: Embedded governance: system itself enforces structure
A27: Hypothesis
B28: Traditional (Canvas + DS) | C28: Knapsack IPE | D28: Efficiency gain
A29: Create design/spec | B29: 10 | C29: 1 | D29: =sum(B29/C29) -> 10
A30: Dev handoff/implement | B30: 25 | C30: 1 | D30: =sum(B30/C30) -> 25
A31: Review + iteration | B31: 15 | C31: 2 | D31: =sum(B31/C31) -> 7.5
A32: Integrate / prep / release | B32: 10 | C32: 1 | D32: =sum(B32/C32) -> 10
A33: Cycle time | B33: =sum(B29:B32) -> 60 | C33: =sum(C29:C32) -> 5 | D33: =sum(B33/C33) -> 12

Sheet Other references
A2: Product team FTE / total company FTE | B2: 0.2 | C2: We use a default assumption of 20%, and allow this to be adjusted to model variations across sectors and firm maturity.
A3: Developers as ratio of product team | B3: 0.85
A4: Designers as ratio of product team | B4: 0.15
A6: ROI of product investment | B6: 3 | C6: We assume a baseline product ROI of 3×, a conservative industry standard representing typical value delivery for non-optimized teams.
A8: Developer average salary | B8: 116576 | C8: Source: Indeed
A9: Designer average salary | B9: 79854 | C9: Source: Indeed
A10: Load cost multiplier | B10: 1.43 | C10: Source: US Bureau of Labor Statistics (Mar 2025)
A12: Avg. product team size | B12: 12

Sheet ACME Corp example
A1: ACME Corporation
A3: COMPANY INFO | D3: DESIGN SYSTEM TEAM | G3: DESIGN SYSTEM TEAM EFFICIENCY GAINS | J3: GAINS OVER TIME (bespoke)
G4: Use baseline adoption rate? | H4: TRUE | J4: Months to next DS maturity | M4: 12
A5: Total staff | B5: 1000 | D5: Design team maturity | E5: 1 | G5: Efficiency gain/user | H5: =if(E5=1, 'Design system reference'!B5, if(E5=2, 'Design system reference'!B6, if(E5=3, 'Design system reference'!B7, if(E5=4, 'Design system reference'!B8, 'Design system reference'!B9)))) -> 0.13209625
A6: Product staff | B6: =sum(B5*'Other references'!B2) -> 200 | D6: Total staff | E6: 12 | G6: Estimated adoption rate | H6: =if(H4=TRUE, if(E5=1, 'Design system reference'!D5, if(E5=2, 'Design system reference'!D6, if(E5=3, 'Design system reference'!D7, if(E5=4, 'Design system reference'!D8, if(E5=5, 'Design system reference'!D9, "N/A"))))), "N/A") -> 0.1 | J6: Month | K6: DS Improvement | L6: DS Maturity | M6: Adoption % | N6: Efficiency gain/user | O6: Org efficiency gain | P6: Efficiency gains $ | Q6: Net versus DS team cost | R6: Cumulative gain (bespoke)
A7: Developers | B7: =sum(B6*'Other references'!B3) -> 170 | D7: Developers | E7: =sum(E6-E8) -> 10 | G7: Manual adoption rate | J7: 0 | K7: =sum(E5) -> 1 | L7: =min(5,(FLOOR(K7,1))) -> 1 | M7: =if($H$4=TRUE, if(L7=1, 'Design system reference'!$D$5, if(L7=2, 'Design system reference'!$D$6, if(L7=3, 'Design system reference'!$D$7, if(L7=4, 'Design system reference'!$D$8, if(L7=5, 'Design system reference'!$D$9, "N/A"))))), if(ISNUMBER(H7), H7, 0)) -> 0.1 | N7: =if(K7<2, 'Design system reference'!$B$5, IF(K7<3, 'Design system reference'!$B$6, IF(K7<4, 'Design system reference'!$B$7, IF(K7<5, 'Design system reference'!$B$8, 'Design system reference'!$B$9)))) -> 0.13209625 | O7: =sum(N7*M7) -> 0.013209625 | R7: 0
A8: Designers | B8: =sum(B6*'Other references'!B4) -> 30 | D8: Designers | E8: =if(E5=1, ROUNDDOWN(E6/(1+'Design system reference'!C5),0), if(E5=2, ROUNDDOWN(E6/(1+'Design system reference'!C6),0), if(E5=3, ROUNDDOWN(E6/(1+'Design system reference'!C7),0), if(E5=4, ROUNDDOWN(E6/(1+'Design system reference'!C8),0), if(E5=5, ROUNDDOWN(E6/(1+'Design system reference'!C9),0), FALSE ))))) -> 2 | G8: Org efficiency gain | H8: =if(isnumber(H7), H7*H5, H6*H5) -> 0.013209625 | J8: 6 | K8: =if(K7=5,K7, SUM(K7+((1/$M$4)*(J8-J7)))) -> 1.5 | L8: =min(5,(FLOOR(K8,1))) -> 1 | M8: =if($H$4=TRUE, if(L8=1, 'Design system reference'!$D$5, if(L8=2, 'Design system reference'!$D$6, if(L8=3, 'Design system reference'!$D$7, if(L8=4, 'Design system reference'!$D$8, if(L8=5, 'Design system reference'!$D$9, "N/A"))))), if(ISNUMBER(H8), H8, 0)) -> 0.1 | N8: =if(K8<2, 'Design system reference'!$B$5, IF(K8<3, 'Design system reference'!$B$6, IF(K8<4, 'Design system reference'!$B$7, IF(K8<5, 'Design system reference'!$B$8, 'Design system reference'!$B$9)))) -> 0.13209625 | O8: =sum(N8*M8) -> 0.013209625 | P8: =sum(($B$20*O8)*0.5) -> 203000.53 | Q8: =sum(P8-$E$11) -> -1692418.7 | R8: =sum(R7+Q8) -> -1692418.7
A9: # of product teams (rounded) | B9: =sum(B6/'Other references'!B12) -> 16.666667 | J9: 12 | K9: =if(K8=5,K8, SUM(K8+((1/$M$4)*(J9-J8)))) -> 2 | L9: =min(5,(FLOOR(K9,1))) -> 2 | M9: =if($H$4=TRUE, if(L9=1, 'Design system reference'!$D$5, if(L9=2, 'Design system reference'!$D$6, if(L9=3, 'Design system reference'!$D$7, if(L9=4, 'Design system reference'!$D$8, if(L9=5, 'Design system reference'!$D$9, "N/A"))))), if(ISNUMBER(H9), H9, 0)) -> 0.3 | N9: =if(K9<2, 'Design system reference'!$B$5, IF(K9<3, 'Design system reference'!$B$6, IF(K9<4, 'Design system reference'!$B$7, IF(K9<5, 'Design system reference'!$B$8, 'Design system reference'!$B$9)))) -> 0.26373062 | O9: =sum(N9*M9) -> 0.079119187 | P9: =sum(($B$20*O9)*0.5) -> 1215873.8 | Q9: =sum(P9-$E$11) -> -679545.41 | R9: =sum(R8+Q9) -> -2371964.1
D10: Design team load cost | E10: =sum((((B11*E7)+(B12*E8))/E6)*B13) -> 157951.6 | G10: Efficiency gains $ | H10: =sum(B20*H8) -> 406001.07 | J10: 18 | K10: =if(K9=5,K9, SUM(K9+((1/$M$4)*(J10-J9)))) -> 2.5 | L10: =min(5,(FLOOR(K10,1))) -> 2 | M10: =if($H$4=TRUE, if(L10=1, 'Design system reference'!$D$5, if(L10=2, 'Design system reference'!$D$6, if(L10=3, 'Design system reference'!$D$7, if(L10=4, 'Design system reference'!$D$8, if(L10=5, 'Design system reference'!$D$9, "N/A"))))), if(ISNUMBER(H10), H10, 0)) -> 0.3 | N10: =if(K10<2, 'Design system reference'!$B$5, IF(K10<3, 'Design system reference'!$B$6, IF(K10<4, 'Design system reference'!$B$7, IF(K10<5, 'Design system reference'!$B$8, 'Design system reference'!$B$9)))) -> 0.26373062 | O10: =sum(N10*M10) -> 0.079119187 | P10: =sum(($B$20*O10)*0.5) -> 1215873.8 | Q10: =sum(P10-$E$11) -> -679545.41 | R10: =sum(R9+Q10) -> -3051509.5
A11: Developer avg salary | B11: =sum('Other references'!B8) -> 116576 | D11: Design team total cost | E11: =sum(E10*E6) -> 1895419.2 | G11: Net versus DS team cost | H11: =sum(H10-E11) -> -1489418.2 | J11: 24 | K11: =if(K10=5,K10, SUM(K10+((1/$M$4)*(J11-J10)))) -> 3 | L11: =min(5,(FLOOR(K11,1))) -> 3 | M11: =if($H$4=TRUE, if(L11=1, 'Design system reference'!$D$5, if(L11=2, 'Design system reference'!$D$6, if(L11=3, 'Design system reference'!$D$7, if(L11=4, 'Design system reference'!$D$8, if(L11=5, 'Design system reference'!$D$9, "N/A"))))), if(ISNUMBER(H11), H11, 0)) -> 0.5 | N11: =if(K11<2, 'Design system reference'!$B$5, IF(K11<3, 'Design system reference'!$B$6, IF(K11<4, 'Design system reference'!$B$7, IF(K11<5, 'Design system reference'!$B$8, 'Design system reference'!$B$9)))) -> 0.461875 | O11: =sum(N11*M11) -> 0.2309375 | P11: =sum(($B$20*O11)*0.5) -> 3548960.4 | Q11: =sum(P11-$E$11) -> 1653541.1 | R11: =sum(R10+Q11) -> -1397968.4
A12: Designer avg salary | B12: =sum('Other references'!B9) -> 79854 | J12: 30 | K12: =if(K11=5,K11, SUM(K11+((1/$M$4)*(J12-J11)))) -> 3.5 | L12: =min(5,(FLOOR(K12,1))) -> 3 | M12: =if($H$4=TRUE, if(L12=1, 'Design system reference'!$D$5, if(L12=2, 'Design system reference'!$D$6, if(L12=3, 'Design system reference'!$D$7, if(L12=4, 'Design system reference'!$D$8, if(L12=5, 'Design system reference'!$D$9, "N/A"))))), if(ISNUMBER(H12), H12, 0)) -> 0.5 | N12: =if(K12<2, 'Design system reference'!$B$5, IF(K12<3, 'Design system reference'!$B$6, IF(K12<4, 'Design system reference'!$B$7, IF(K12<5, 'Design system reference'!$B$8, 'Design system reference'!$B$9)))) -> 0.461875 | O12: =sum(N12*M12) -> 0.2309375 | P12: =sum(($B$20*O12)*0.5) -> 3548960.4 | Q12: =sum(P12-$E$11) -> 1653541.1 | R12: =sum(R11+Q12) -> 255572.77
A13: Load cost multiplier | B13: =sum('Other references'!B10) -> 1.43 | J13: 36 | K13: =if(K12=5,K12, SUM(K12+((1/$M$4)*(J13-J12)))) -> 4 | L13: =min(5,(FLOOR(K13,1))) -> 4 | M13: =if($H$4=TRUE, if(L13=1, 'Design system reference'!$D$5, if(L13=2, 'Design system reference'!$D$6, if(L13=3, 'Design system reference'!$D$7, if(L13=4, 'Design system reference'!$D$8, if(L13=5, 'Design system reference'!$D$9, "N/A"))))), if(ISNUMBER(H19), H19, 0)) -> 0.8 | N13: =if(K13<2, 'Design system reference'!$B$5, IF(K13<3, 'Design system reference'!$B$6, IF(K13<4, 'Design system reference'!$B$7, IF(K13<5, 'Design system reference'!$B$8, 'Design system reference'!$B$9)))) -> 0.59397125 | O13: =sum(N13*M13) -> 0.475177 | P13: =sum(($B$20*O13)*0.5) -> 7302340.9 | Q13: =sum(P13-$E$11) -> 5406921.7 | R13: =sum(R12+Q13) -> 5662494.4
J14: 42 | K14: =if(K13=5,K13, SUM(K13+((1/$M$4)*(J14-J13)))) -> 4.5 | L14: =min(5,(FLOOR(K14,1))) -> 4 | M14: =if($H$4=TRUE, if(L14=1, 'Design system reference'!$D$5, if(L14=2, 'Design system reference'!$D$6, if(L14=3, 'Design system reference'!$D$7, if(L14=4, 'Design system reference'!$D$8, if(L14=5, 'Design system reference'!$D$9, "N/A"))))), if(ISNUMBER(H20), H20, 0)) -> 0.8 | N14: =if(K14<2, 'Design system reference'!$B$5, IF(K14<3, 'Design system reference'!$B$6, IF(K14<4, 'Design system reference'!$B$7, IF(K14<5, 'Design system reference'!$B$8, 'Design system reference'!$B$9)))) -> 0.59397125 | O14: =sum(N14*M14) -> 0.475177 | P14: =sum(($B$20*O14)*0.5) -> 7302340.9 | Q14: =sum(P14-$E$11) -> 5406921.7 | R14: =sum(R13+Q14) -> 11069416
A15: Developer load cost | B15: =sum(B11*B13) -> 166703.68 | J15: 48 | K15: =if(K14=5,K14, SUM(K14+((1/$M$4)*(J15-J14)))) -> 5 | L15: =min(5,(FLOOR(K15,1))) -> 5 | M15: =if($H$4=TRUE, if(L15=1, 'Design system reference'!$D$5, if(L15=2, 'Design system reference'!$D$6, if(L15=3, 'Design system reference'!$D$7, if(L15=4, 'Design system reference'!$D$8, if(L15=5, 'Design system reference'!$D$9, "N/A"))))), if(ISNUMBER(H21), H21, 0)) -> 0.95 | N15: =if(K15<2, 'Design system reference'!$B$5, IF(K15<3, 'Design system reference'!$B$6, IF(K15<4, 'Design system reference'!$B$7, IF(K15<5, 'Design system reference'!$B$8, 'Design system reference'!$B$9)))) -> 0.66001937 | O15: =sum(N15*M15) -> 0.62701841 | P15: =sum(($B$20*O15)*0.5) -> 9635782.4 | Q15: =sum(P15-$E$11) -> 7740363.1 | R15: =sum(R14+Q15) -> 18809779
A16: Designer load cost | B16: =sum(B12*B13) -> 114191.22 | J16: 54 | K16: =if(K15=5,K15, SUM(K15+((1/$M$4)*(J16-J15)))) -> 5 | L16: =min(5,(FLOOR(K16,1))) -> 5 | M16: =if($H$4=TRUE, if(L16=1, 'Design system reference'!$D$5, if(L16=2, 'Design system reference'!$D$6, if(L16=3, 'Design system reference'!$D$7, if(L16=4, 'Design system reference'!$D$8, if(L16=5, 'Design system reference'!$D$9, "N/A"))))), if(ISNUMBER(H22), H22, 0)) -> 0.95 | N16: =if(K16<2, 'Design system reference'!$B$5, IF(K16<3, 'Design system reference'!$B$6, IF(K16<4, 'Design system reference'!$B$7, IF(K16<5, 'Design system reference'!$B$8, 'Design system reference'!$B$9)))) -> 0.66001937 | O16: =sum(N16*M16) -> 0.62701841 | P16: =sum(($B$20*O16)*0.5) -> 9635782.4 | Q16: =sum(P16-$E$11) -> 7740363.1 | R16: =sum(R15+Q16) -> 26550142
J17: 60 | K17: =if(K16=5,K16, SUM(K16+((1/$M$4)*(J17-J16)))) -> 5 | L17: =min(5,(FLOOR(K17,1))) -> 5 | M17: =if($H$4=TRUE, if(L17=1, 'Design system reference'!$D$5, if(L17=2, 'Design system reference'!$D$6, if(L17=3, 'Design system reference'!$D$7, if(L17=4, 'Design system reference'!$D$8, if(L17=5, 'Design system reference'!$D$9, "N/A"))))), if(ISNUMBER(H17), H17, 0)) -> 0.95 | N17: =if(K17<2, 'Design system reference'!$B$5, IF(K17<3, 'Design system reference'!$B$6, IF(K17<4, 'Design system reference'!$B$7, IF(K17<5, 'Design system reference'!$B$8, 'Design system reference'!$B$9)))) -> 0.66001937 | O17: =sum(N17*M17) -> 0.62701841 | P17: =sum(($B$20*O17)*0.5) -> 9635782.4 | Q17: =sum(P17-$E$11) -> 7740363.1 | R17: =sum(R16+Q17) -> 34290505
A18: Prod team load cost | B18: =sum(((B15*B7)+(B12*B8))/B6) -> 153676.23
G19: KNAPSACK OPERATIONAL EFFICIENCY GAINS | J19: GAINS OVER TIME (Knapsack)
A20: Baseline product spend | B20: =sum(B18*B6) -> 30735246 | G20: Flat rate | J20: Months to next DS maturity | M20: DS1-2, DS2-3 | N20: 6 | P20: DS3-4, DS4-5 | Q20: 9
G21: Annual contract cost | H21: =sum('Knapsack reference'!B4) -> 150000
A22: ROI on product spend | B22: =sum('Other references'!B6) -> 3 | G22: Net reduction in DS team cost | H22: =sum((E11*'Knapsack reference'!B3)-H21) -> 134312.89 | J22: Month | K22: DS Improvement | L22: DS Maturity | M22: Adoption % | N22: Efficiency gain/user | O22: Org efficiency gain | P22: Efficiency gains $ | Q22: Net versus DS team cost | R22: Cumulative gain (Knapsack) | S22: Differential | T22: KS efficiency gain to product spend | V22: ROI on product spend
J23: 0 | K23: =sum(E5) -> 1 | L23: =floor(K23,1) -> 1 | M23: =if($H$4=TRUE, if(L23=1, 'Design system reference'!D$5, if(L23=2, 'Design system reference'!D$6, if(L23=3, 'Design system reference'!D$7, if(L23=4, 'Design system reference'!D$8, if(L23=5, 'Design system reference'!D$9, "N/A"))))), if(ISNUMBER($H$7), $H$7, 0)) -> 0.1 | N23: =if(L23<2, 'Design system reference'!$B$5, IF(L23<3, 'Design system reference'!$B$6, IF(L23<4, 'Design system reference'!$B$7, IF(L23<5, 'Design system reference'!$B$8, 'Design system reference'!$B$9)))) -> 0.13209625 | O23: =sum(N23*M23) -> 0.013209625 | R23: 0 | V23: =sum($B$22) -> 3
A24: Revenue | B24: =sum(B20*B22) -> 92205737 | J24: 6 | K24: =if(K23=5,K23, IF(K23<3, SUM(K23+((1/$N$20)*(J24-J23))), IF(K23>=3, SUM(K23+((1/$Q$20)*(J24-J23)))))) -> 2 | L24: =floor(K24,1) -> 2 | M24: =if($H$4=TRUE, if(L24=1, 'Design system reference'!D$5, if(L24=2, 'Design system reference'!D$6, if(L24=3, 'Design system reference'!D$7, if(L24=4, 'Design system reference'!D$8, if(L24=5, 'Design system reference'!D$9, "N/A"))))), if(ISNUMBER($H$7), $H$7, 0)) -> 0.3 | N24: =if(L24<2, 'Design system reference'!$B$5, IF(L24<3, 'Design system reference'!$B$6, IF(L24<4, 'Design system reference'!$B$7, IF(L24<5, 'Design system reference'!$B$8, 'Design system reference'!$B$9)))) -> 0.26373062 | O24: =sum(N24*M24) -> 0.079119187 | P24: =sum(($B$20*O24)*0.5) -> 1215873.8 | Q24: =sum(P24-$E$11+$H$22) -> -545232.52 | R24: =sum(R23+Q24) -> -545232.52 | S24: =sum(R24-R8) -> 1147186.2 | T24: =sum(S24/B20) -> 0.037324777 | V24: =sum($B$22*(1+T24)) -> 3.1119743
J25: 12 | K25: =if(K24=5,K24, IF(K24<3, SUM(K24+((1/$N$20)*(J25-J24))), IF(K24>=3, SUM(K24+((1/$Q$20)*(J25-J24)))))) -> 3 | L25: =floor(K25,1) -> 3 | M25: =if($H$4=TRUE, if(L25=1, 'Design system reference'!D$5, if(L25=2, 'Design system reference'!D$6, if(L25=3, 'Design system reference'!D$7, if(L25=4, 'Design system reference'!D$8, if(L25=5, 'Design system reference'!D$9, "N/A"))))), if(ISNUMBER($H$7), $H$7, 0)) -> 0.5 | N25: =if(L25<2, 'Design system reference'!$B$5, IF(L25<3, 'Design system reference'!$B$6, IF(L25<4, 'Design system reference'!$B$7, IF(L25<5, 'Design system reference'!$B$8, 'Design system reference'!$B$9)))) -> 0.461875 | O25: =sum(N25*M25) -> 0.2309375 | P25: =sum(($B$20*O25)*0.5) -> 3548960.4 | Q25: =sum(P25-$E$11+$H$22) -> 1787854 | R25: =sum(R24+Q25) -> 1242621.5 | S25: =sum(R25-R9) -> 3614585.6 | T25: =sum(S25/$B$20) -> 0.11760393 | V25: =sum($B$22*(1+T25)) -> 3.3528118
J26: 18 | K26: =if(K25=5,K25, IF(K25<3, SUM(K25+((1/$N$20)*(J26-J25))), IF(K25>=3, SUM(K25+((1/$Q$20)*(J26-J25)))))) -> 3.6666667 | L26: =MIN(5,(floor(K26,1))) -> 3 | M26: =if($H$4=TRUE, if(L26=1, 'Design system reference'!D$5, if(L26=2, 'Design system reference'!D$6, if(L26=3, 'Design system reference'!D$7, if(L26=4, 'Design system reference'!D$8, if(L26=5, 'Design system reference'!D$9, "N/A"))))), if(ISNUMBER($H$7), $H$7, 0)) -> 0.5 | N26: =if(L26<2, 'Design system reference'!$B$5, IF(L26<3, 'Design system reference'!$B$6, IF(L26<4, 'Design system reference'!$B$7, IF(L26<5, 'Design system reference'!$B$8, 'Design system reference'!$B$9)))) -> 0.461875 | O26: =sum(N26*M26) -> 0.2309375 | P26: =sum(($B$20*O26)*0.5) -> 3548960.4 | Q26: =sum(P26-$E$11+$H$22) -> 1787854 | R26: =sum(R25+Q26) -> 3030475.5 | S26: =sum(R26-R10) -> 6081985.1 | T26: =sum(S26/$B$20) -> 0.19788308 | V26: =sum($B$22*(1+T26)) -> 3.5936492
