Workbook
Name Vendors_List: 'Lookups - Rates'!$H$2:$H$3
Name Scenario_Selected: Assumptions!$B$7
Name Scenario_Table: Assumptions!$A$9:$D$12
Name Milestone_Activities: Milestones!$B$2:$B$40
Name Complexity_Tasks: 'Lookups - Complexity'!$B$2:$B$26
Name Roles_List: 'Lookups - Rates'!$I$2:$I$100

Sheet Inputs
A1: Estimation Inputs
A3: Delivery Model | B3: Hybrid Service Delivery
A4: Journey | B4: 1 Journey
A5: Deployment | B5: 1 Deployment
A6: Default Complexity | B6: Medium
A7: Readiness/Maturity Multiplier | B7: =IFERROR('Readiness & Maturity'!$B$16,1)
A8: Readiness Level (calculated) | B8: =IFERROR('Readiness & Maturity'!$B$15,"-")

Sheet Lookups - JourneyDeployment
A1: Journey options | D1: Deployment options | G1: Complexity | I1: Delivery owner | K1: Role mapping (WBS → standard rate role)
A2: Journey | B2: Multiplier | D2: Deployment | E2: Multiplier | G2: Option | I2: Option | K2: WBS Role | L2: Standard Role
A3: 1 Journey | B3: 1 | D3: 1 Deployment | E3: 1 | G3: Low | I3: Knapsack | K3: CX Partner | L3: CX Partner
A4: 2–3 Journeys | B4: 1.5 | D4: 2 Deployments | E4: 1.4 | G4: Medium | I4: Client/SCE | K4: Project Manager | L4: Project Manager
A5: 4–6 Journeys | B5: 2 | D5: 3–5 Deployments | E5: 2 | G5: High | K5: Engineer | L5: Solution Analyst
A6: 7+ Journeys | B6: 3 | D6: 6+ Deployments | E6: 2.8 | K6: SME | L6: SME
K7: Design Lead | L7: Executive

Sheet Rates
A1: Standard Role | B1: Provider | C1: Rate ($/hr) | D1: Source | E1: Key
A2: CX Partner | B2: Knapsack | C2: 600 | D2: Knapsack bill rate | E2: CX Partner|Knapsack
A3: Senior Solution Analyst | B3: Knapsack | C3: 550 | D3: Knapsack bill rate | E3: Senior Solution Analyst|Knapsack
A4: Solution Analyst | B4: Knapsack | C4: 400 | D4: Knapsack bill rate | E4: Solution Analyst|Knapsack
A5: Project Manager | B5: Knapsack | C5: 400 | D5: Knapsack bill rate | E5: Project Manager|Knapsack
A6: SME | B6: Knapsack | C6: 750 | D6: Knapsack bill rate | E6: SME|Knapsack
A7: Executive | B7: Knapsack | C7: 825 | D7: Knapsack bill rate | E7: Executive|Knapsack
A8: CX Partner | B8: Client/SCE | C8: 140 | D8: Default CSE rate (edit) | E8: CX Partner|Client/SCE
A9: Senior Solution Analyst | B9: Client/SCE | C9: 140 | D9: Default CSE rate (edit) | E9: Senior Solution Analyst|Client/SCE
A10: Solution Analyst | B10: Client/SCE | C10: 140 | D10: Default CSE rate (edit) | E10: Solution Analyst|Client/SCE
A11: Project Manager | B11: Client/SCE | C11: 140 | D11: Default CSE rate (edit) | E11: Project Manager|Client/SCE
A12: SME | B12: Client/SCE | C12: 140 | D12: Default CSE rate (edit) | E12: SME|Client/SCE
A13: Executive | B13: Client/SCE | C13: 140 | D13: Default CSE rate (edit) | E13: Executive|Client/SCE

Sheet Readiness & Maturity
A1: Readiness & Maturity (PCRI-driven)
A3: PCRI is calculated on the 'PCRI Assessment' tab. Outputs below drive estimation multipliers and WBS prescription.
A5: PCRI Score | B5: ='PCRI Assessment'!$J$20 | D5: Archetype | E5: Default Multiplier | F5: Notes
A6: Archetype | B6: ='PCRI Assessment'!$J$21 | D6: Builder | E6: 1.5 | F6: More foundation + enablement
A7: Foundation (effective) | B7: ='PCRI Assessment'!$J$15 | D7: Adopter | E7: 1.2 | F7: Enablement sprint + adoption
A8: AI Readiness (effective) | B8: ='PCRI Assessment'!$J$16 | D8: Optimizer | E8: 1 | F8: Standard delivery
A9: Governance (effective) | B9: ='PCRI Assessment'!$J$17 | D9: Transformer | E9: 0.9 | F9: Less enablement; faster execution
A10: Delivery (effective) | B10: ='PCRI Assessment'!$J$18
A11: Culture (effective) | B11: ='PCRI Assessment'!$J$19
A12: AI Gate Applied? | B12: ='PCRI Assessment'!$J$13
A13: Delivery Gate Applied? | B13: ='PCRI Assessment'!$J$14
A14: Multiplier mapping (edit if needed) | D14: Archetype → Multiplier Mapping
A15: Readiness level (used by Inputs) | B15: =B6 | D15: Edit the multipliers in column E to calibrate by archetype.
A16: Multiplier | B16: =IFERROR(XLOOKUP(B6,$D$6:$D$9,$E$6:$E$9),1)

Sheet Activity Settings
A1: Phase | B1: Activity / Milestone | C1: # Subtasks | D1: Complexity (input) | E1: Base Hours (lookup) | F1: Readiness Mult | G1: Journey Mult | H1: Deployment Mult | I1: Adjusted Total Hours | J1: Adjusted Hours / Subtask | K1: Owner Override (Hybrid) | L1: Owner Used | M1: Activity Key | N1: PCRI Mult (include/prescribe)
A2: Implementation + Onboarding | B2: Stakeholder Alignment Workshops | C2: 5 | D2: =Inputs!$B$6 | E2: =IFERROR(INDEX('Lookups - Complexity'!$C$2:$E$200, MATCH(M2,'Lookups - Complexity'!$F$2:$F$200, 0), MATCH(D2, {"Low","Medium","High"}, 0)), 0) | F2: =Inputs!$B$7 | G2: =IFERROR(XLOOKUP(Inputs!$B$4,'Lookups - JourneyDeployment'!$A$3:$A$6,'Lookups - JourneyDeployment'!$B$3:$B$6),1) | H2: =IFERROR(XLOOKUP(Inputs!$B$5,'Lookups - JourneyDeployment'!$D$3:$D$6,'Lookups - JourneyDeployment'!$E$3:$E$6),1) | I2: =E2*F2*G2*H2*N2 | J2: =IF(C2=0,0,I2/C2) | K2: Knapsack | L2: =IF(Inputs!$B$3="Managed Service Delivery","Knapsack",IF(K2="","Knapsack",K2)) | M2: =A2&"|"&B2 | N2: =IFERROR(XLOOKUP(M2,'PCRI WBS Mapping'!$C$2:$C$200,'PCRI WBS Mapping'!$M$2:$M$200),1)
A3: Implementation + Onboarding | B3: Program management and coordination | C3: 5 | D3: =Inputs!$B$6 | E3: =IFERROR(INDEX('Lookups - Complexity'!$C$2:$E$200, MATCH(M3,'Lookups - Complexity'!$F$2:$F$200, 0), MATCH(D3, {"Low","Medium","High"}, 0)), 0) | F3: =Inputs!$B$7 | G3: =IFERROR(XLOOKUP(Inputs!$B$4,'Lookups - JourneyDeployment'!$A$3:$A$6,'Lookups - JourneyDeployment'!$B$3:$B$6),1) | H3: =IFERROR(XLOOKUP(Inputs!$B$5,'Lookups - JourneyDeployment'!$D$3:$D$6,'Lookups - JourneyDeployment'!$E$3:$E$6),1) | I3: =E3*F3*G3*H3*N3 | J3: =IF(C3=0,0,I3/C3) | K3: Knapsack | L3: =IF(Inputs!$B$3="Managed Service Delivery","Knapsack",IF(K3="","Knapsack",K3)) | M3: =A3&"|"&B3 | N3: =IFERROR(XLOOKUP(M3,'PCRI WBS Mapping'!$C$2:$C$200,'PCRI WBS Mapping'!$M$2:$M$200),1)
A4: Implementation + Onboarding | B4: Communication Launch Plan | C4: 5 | D4: =Inputs!$B$6 | E4: =IFERROR(INDEX('Lookups - Complexity'!$C$2:$E$200, MATCH(M4,'Lookups - Complexity'!$F$2:$F$200, 0), MATCH(D4, {"Low","Medium","High"}, 0)), 0) | F4: =Inputs!$B$7 | G4: =IFERROR(XLOOKUP(Inputs!$B$4,'Lookups - JourneyDeployment'!$A$3:$A$6,'Lookups - JourneyDeployment'!$B$3:$B$6),1) | H4: =IFERROR(XLOOKUP(Inputs!$B$5,'Lookups - JourneyDeployment'!$D$3:$D$6,'Lookups - JourneyDeployment'!$E$3:$E$6),1) | I4: =E4*F4*G4*H4*N4 | J4: =IF(C4=0,0,I4/C4) | K4: Knapsack | L4: =IF(Inputs!$B$3="Managed Service Delivery","Knapsack",IF(K4="","Knapsack",K4)) | M4: =A4&"|"&B4 | N4: =IFERROR(XLOOKUP(M4,'PCRI WBS Mapping'!$C$2:$C$200,'PCRI WBS Mapping'!$M$2:$M$200),1)
A5: Implementation + Onboarding | B5: Preparation | C5: 5 | D5: =Inputs!$B$6 | E5: =IFERROR(INDEX('Lookups - Complexity'!$C$2:$E$200, MATCH(M5,'Lookups - Complexity'!$F$2:$F$200, 0), MATCH(D5, {"Low","Medium","High"}, 0)), 0) | F5: =Inputs!$B$7 | G5: =IFERROR(XLOOKUP(Inputs!$B$4,'Lookups - JourneyDeployment'!$A$3:$A$6,'Lookups - JourneyDeployment'!$B$3:$B$6),1) | H5: =IFERROR(XLOOKUP(Inputs!$B$5,'Lookups - JourneyDeployment'!$D$3:$D$6,'Lookups - JourneyDeployment'!$E$3:$E$6),1) | I5: =E5*F5*G5*H5*N5 | J5: =IF(C5=0,0,I5/C5) | K5: Knapsack | L5: =IF(Inputs!$B$3="Managed Service Delivery","Knapsack",IF(K5="","Knapsack",K5)) | M5: =A5&"|"&B5 | N5: =IFERROR(XLOOKUP(M5,'PCRI WBS Mapping'!$C$2:$C$200,'PCRI WBS Mapping'!$M$2:$M$200),1)
A6: Implementation + Onboarding | B6: Local install support | C6: 5 | D6: =Inputs!$B$6 | E6: =IFERROR(INDEX('Lookups - Complexity'!$C$2:$E$200, MATCH(M6,'Lookups - Complexity'!$F$2:$F$200, 0), MATCH(D6, {"Low","Medium","High"}, 0)), 0) | F6: =Inputs!$B$7 | G6: =IFERROR(XLOOKUP(Inputs!$B$4,'Lookups - JourneyDeployment'!$A$3:$A$6,'Lookups - JourneyDeployment'!$B$3:$B$6),1) | H6: =IFERROR(XLOOKUP(Inputs!$B$5,'Lookups - JourneyDeployment'!$D$3:$D$6,'Lookups - JourneyDeployment'!$E$3:$E$6),1) | I6: =E6*F6*G6*H6*N6 | J6: =IF(C6=0,0,I6/C6) | K6: Knapsack | L6: =IF(Inputs!$B$3="Managed Service Delivery","Knapsack",IF(K6="","Knapsack",K6)) | M6: =A6&"|"&B6 | N6: =IFERROR(XLOOKUP(M6,'PCRI WBS Mapping'!$C$2:$C$200,'PCRI WBS Mapping'!$M$2:$M$200),1)
A7: Implementation + Onboarding | B7: Component rendering | C7: 5 | D7: =Inputs!$B$6 | E7: =IFERROR(INDEX('Lookups - Complexity'!$C$2:$E$200, MATCH(M7,'Lookups - Complexity'!$F$2:$F$200, 0), MATCH(D7, {"Low","Medium","High"}, 0)), 0) | F7: =Inputs!$B$7 | G7: =IFERROR(XLOOKUP(Inputs!$B$4,'Lookups - JourneyDeployment'!$A$3:$A$6,'Lookups - JourneyDeployment'!$B$3:$B$6),1) | H7: =IFERROR(XLOOKUP(Inputs!$B$5,'Lookups - JourneyDeployment'!$D$3:$D$6,'Lookups - JourneyDeployment'!$E$3:$E$6),1) | I7: =E7*F7*G7*H7*N7 | J7: =IF(C7=0,0,I7/C7) | K7: Knapsack | L7: =IF(Inputs!$B$3="Managed Service Delivery","Knapsack",IF(K7="","Knapsack",K7)) | M7: =A7&"|"&B7 | N7: =IFERROR(XLOOKUP(M7,'PCRI WBS Mapping'!$C$2:$C$200,'PCRI WBS Mapping'!$M$2:$M$200),1)
A8: Implementation + Onboarding | B8: SME support for rendering | C8: 5 | D8: =Inputs!$B$6 | E8: =IFERROR(INDEX('Lookups - Complexity'!$C$2:$E$200, MATCH(M8,'Lookups - Complexity'!$F$2:$F$200, 0), MATCH(D8, {"Low","Medium","High"}, 0)), 0) | F8: =Inputs!$B$7 | G8: =IFERROR(XLOOKUP(Inputs!$B$4,'Lookups - JourneyDeployment'!$A$3:$A$6,'Lookups - JourneyDeployment'!$B$3:$B$6),1) | H8: =IFERROR(XLOOKUP(Inputs!$B$5,'Lookups - JourneyDeployment'!$D$3:$D$6,'Lookups - JourneyDeployment'!$E$3:$E$6),1) | I8: =E8*F8*G8*H8*N8 | J8: =IF(C8=0,0,I8/C8) | K8: Knapsack | L8: =IF(Inputs!$B$3="Managed Service Delivery","Knapsack",IF(K8="","Knapsack",K8)) | M8: =A8&"|"&B8 | N8: =IFERROR(XLOOKUP(M8,'PCRI WBS Mapping'!$C$2:$C$200,'PCRI WBS Mapping'!$M$2:$M$200),1)
A9: Implementation + Onboarding | B9: Deployment support | C9: 5 | D9: =Inputs!$B$6 | E9: =IFERROR(INDEX('Lookups - Complexity'!$C$2:$E$200, MATCH(M9,'Lookups - Complexity'!$F$2:$F$200, 0), MATCH(D9, {"Low","Medium","High"}, 0)), 0) | F9: =Inputs!$B$7 | G9: =IFERROR(XLOOKUP(Inputs!$B$4,'Lookups - JourneyDeployment'!$A$3:$A$6,'Lookups - JourneyDeployment'!$B$3:$B$6),1) | H9: =IFERROR(XLOOKUP(Inputs!$B$5,'Lookups - JourneyDeployment'!$D$3:$D$6,'Lookups - JourneyDeployment'!$E$3:$E$6),1) | I9: =E9*F9*G9*H9*N9 | J9: =IF(C9=0,0,I9/C9) | K9: Knapsack | L9: =IF(Inputs!$B$3="Managed Service Delivery","Knapsack",IF(K9="","Knapsack",K9)) | M9: =A9&"|"&B9 | N9: =IFERROR(XLOOKUP(M9,'PCRI WBS Mapping'!$C$2:$C$200,'PCRI WBS Mapping'!$M$2:$M$200),1)
A10: Scaled Rollout and Adoption | B10: Program management and Steering Committee coordination | C10: 5 | D10: =Inputs!$B$6 | E10: =IFERROR(INDEX('Lookups - Complexity'!$C$2:$E$200, MATCH(M10,'Lookups - Complexity'!$F$2:$F$200, 0), MATCH(D10, {"Low","Medium","High"}, 0)), 0) | F10: =Inputs!$B$7 | G10: =IFERROR(XLOOKUP(Inputs!$B$4,'Lookups - JourneyDeployment'!$A$3:$A$6,'Lookups - JourneyDeployment'!$B$3:$B$6),1) | H10: =IFERROR(XLOOKUP(Inputs!$B$5,'Lookups - JourneyDeployment'!$D$3:$D$6,'Lookups - JourneyDeployment'!$E$3:$E$6),1) | I10: =E10*F10*G10*H10*N10 | J10: =IF(C10=0,0,I10/C10) | K10: Knapsack | L10: =IF(Inputs!$B$3="Managed Service Delivery","Knapsack",IF(K10="","Knapsack",K10)) | M10: =A10&"|"&B10 | N10: =IFERROR(XLOOKUP(M10,'PCRI WBS Mapping'!$C$2:$C$200,'PCRI WBS Mapping'!$M$2:$M$200),1)
A11: Scaled Rollout and Adoption | B11: Facilitating and supporting deliverables | C11: 5 | D11: =Inputs!$B$6 | E11: =IFERROR(INDEX('Lookups - Complexity'!$C$2:$E$200, MATCH(M11,'Lookups - Complexity'!$F$2:$F$200, 0), MATCH(D11, {"Low","Medium","High"}, 0)), 0) | F11: =Inputs!$B$7 | G11: =IFERROR(XLOOKUP(Inputs!$B$4,'Lookups - JourneyDeployment'!$A$3:$A$6,'Lookups - JourneyDeployment'!$B$3:$B$6),1) | H11: =IFERROR(XLOOKUP(Inputs!$B$5,'Lookups - JourneyDeployment'!$D$3:$D$6,'Lookups - JourneyDeployment'!$E$3:$E$6),1) | I11: =E11*F11*G11*H11*N11 | J11: =IF(C11=0,0,I11/C11) | K11: Knapsack | L11: =IF(Inputs!$B$3="Managed Service Delivery","Knapsack",IF(K11="","Knapsack",K11)) | M11: =A11&"|"&B11 | N11: =IFERROR(XLOOKUP(M11,'PCRI WBS Mapping'!$C$2:$C$200,'PCRI WBS Mapping'!$M$2:$M$200),1)
A12: Scaled Rollout and Adoption | B12: Change Readiness Assessment | C12: 5 | D12: =Inputs!$B$6 | E12: =IFERROR(INDEX('Lookups - Complexity'!$C$2:$E$200, MATCH(M12,'Lookups - Complexity'!$F$2:$F$200, 0), MATCH(D12, {"Low","Medium","High"}, 0)), 0) | F12: =Inputs!$B$7 | G12: =IFERROR(XLOOKUP(Inputs!$B$4,'Lookups - JourneyDeployment'!$A$3:$A$6,'Lookups - JourneyDeployment'!$B$3:$B$6),1) | H12: =IFERROR(XLOOKUP(Inputs!$B$5,'Lookups - JourneyDeployment'!$D$3:$D$6,'Lookups - JourneyDeployment'!$E$3:$E$6),1) | I12: =E12*F12*G12*H12*N12 | J12: =IF(C12=0,0,I12/C12) | K12: Knapsack | L12: =IF(Inputs!$B$3="Managed Service Delivery","Knapsack",IF(K12="","Knapsack",K12)) | M12: =A12&"|"&B12 | N12: =IFERROR(XLOOKUP(M12,'PCRI WBS Mapping'!$C$2:$C$200,'PCRI WBS Mapping'!$M$2:$M$200),1)
A13: Scaled Rollout and Adoption | B13: FDE led Implementation + Architecture + Governance | C13: 4 | D13: =Inputs!$B$6 | E13: =IFERROR(INDEX('Lookups - Complexity'!$C$2:$E$200, MATCH(M13,'Lookups - Complexity'!$F$2:$F$200, 0), MATCH(D13, {"Low","Medium","High"}, 0)), 0) | F13: =Inputs!$B$7 | G13: =IFERROR(XLOOKUP(Inputs!$B$4,'Lookups - JourneyDeployment'!$A$3:$A$6,'Lookups - JourneyDeployment'!$B$3:$B$6),1) | H13: =IFERROR(XLOOKUP(Inputs!$B$5,'Lookups - JourneyDeployment'!$D$3:$D$6,'Lookups - JourneyDeployment'!$E$3:$E$6),1) | I13: =E13*F13*G13*H13*N13 | J13: =IF(C13=0,0,I13/C13) | K13: Knapsack | L13: =IF(Inputs!$B$3="Managed Service Delivery","Knapsack",IF(K13="","Knapsack",K13)) | M13: =A13&"|"&B13 | N13: =IFERROR(XLOOKUP(M13,'PCRI WBS Mapping'!$C$2:$C$200,'PCRI WBS Mapping'!$M$2:$M$200),1)
... A60: Optimization and Continued Support | B60: AI Contextual Capabilities – Feedback Loop + Knowledge Refresh | C60: 4 | D60: =Inputs!$B$6 | E60: =IFERROR(INDEX('Lookups - Complexity'!$C$2:$E$200, MATCH(M60,'Lookups - Complexity'!$F$2:$F$200, 0), MATCH(D60, {"Low","Medium","High"}, 0)), 0) | F60: =Inputs!$B$7 | G60: =IFERROR(XLOOKUP(Inputs!$B$4,'Lookups - JourneyDeployment'!$A$3:$A$6,'Lookups - JourneyDeployment'!$B$3:$B$6),1) | H60: =IFERROR(XLOOKUP(Inputs!$B$5,'Lookups - JourneyDeployment'!$D$3:$D$6,'Lookups - JourneyDeployment'!$E$3:$E$6),1) | I60: =E60*F60*G60*H60*N60 | J60: =IF(C60=0,0,I60/C60) | K60: Knapsack | L60: =IF(Inputs!$B$3="Managed Service Delivery","Knapsack",IF(K60="","Knapsack",K60)) | M60: =A60&"|"&B60 | N60: =IFERROR(XLOOKUP(M60,'PCRI WBS Mapping'!$C$2:$C$200,'PCRI WBS Mapping'!$M$2:$M$200),1)

Sheet WBS - Estimate
A1: Phase | B1: Activity / Milestone | C1: Subtask | D1: Deliverable | E1: Deliverable Description | F1: Knapsack Role Description | G1: Accountable Party | H1: Role | I1: Timeline (Weeks) | J1: Standard Role | K1: Activity Key | L1: Hours / Subtask (adjusted) | M1: Owner Used | N1: Rate ($/hr) | O1: Est. Cost
A2: Implementation + Onboarding | B2: Stakeholder Alignment Workshops | C2: Identify executive and operational stakeholders | F2: CX Partner - Change Management SME | G2: Adobe | H2: CX Partner | I2: 1–2 | J2: =IFERROR(XLOOKUP(H2,'Lookups - JourneyDeployment'!$K$3:$K$7,'Lookups - JourneyDeployment'!$L$3:$L$7),"") | K2: =A2&"|"&B2 | L2: =IFERROR(XLOOKUP(K2,'Activity Settings'!$M$2:$M$200,'Activity Settings'!$J$2:$J$200),0) | M2: =IFERROR(XLOOKUP(K2,'Activity Settings'!$M$2:$M$200,'Activity Settings'!$L$2:$L$200),"Knapsack") | N2: =IFERROR(XLOOKUP(J2&"|"&M2,Rates!$E$2:$E$13,Rates!$C$2:$C$13),0) | O2: =L2*N2
A3: Implementation + Onboarding | B3: Stakeholder Alignment Workshops | C3: Conduct alignment workshops and capture insights | F3: CX Partner - Change Management SME | G3: Adobe | H3: CX Partner | I3: 1–2 | J3: =IFERROR(XLOOKUP(H3,'Lookups - JourneyDeployment'!$K$3:$K$7,'Lookups - JourneyDeployment'!$L$3:$L$7),"") | K3: =A3&"|"&B3 | L3: =IFERROR(XLOOKUP(K3,'Activity Settings'!$M$2:$M$200,'Activity Settings'!$J$2:$J$200),0) | M3: =IFERROR(XLOOKUP(K3,'Activity Settings'!$M$2:$M$200,'Activity Settings'!$L$2:$L$200),"Knapsack") | N3: =IFERROR(XLOOKUP(J3&"|"&M3,Rates!$E$2:$E$13,Rates!$C$2:$C$13),0) | O3: =L3*N3
A4: Implementation + Onboarding | B4: Stakeholder Alignment Workshops | C4: Develop stakeholder map and influence matrix | F4: CX Partner - Change Management SME | G4: Adobe | H4: CX Partner | I4: 1–2 | J4: =IFERROR(XLOOKUP(H4,'Lookups - JourneyDeployment'!$K$3:$K$7,'Lookups - JourneyDeployment'!$L$3:$L$7),"") | K4: =A4&"|"&B4 | L4: =IFERROR(XLOOKUP(K4,'Activity Settings'!$M$2:$M$200,'Activity Settings'!$J$2:$J$200),0) | M4: =IFERROR(XLOOKUP(K4,'Activity Settings'!$M$2:$M$200,'Activity Settings'!$L$2:$L$200),"Knapsack") | N4: =IFERROR(XLOOKUP(J4&"|"&M4,Rates!$E$2:$E$13,Rates!$C$2:$C$13),0) | O4: =L4*N4
A5: Implementation + Onboarding | B5: Stakeholder Alignment Workshops | C5: Draft communication strategy and feedback cadence | F5: CX Partner - Change Management SME | G5: Adobe | H5: CX Partner | I5: 1–2 | J5: =IFERROR(XLOOKUP(H5,'Lookups - JourneyDeployment'!$K$3:$K$7,'Lookups - JourneyDeployment'!$L$3:$L$7),"") | K5: =A5&"|"&B5 | L5: =IFERROR(XLOOKUP(K5,'Activity Settings'!$M$2:$M$200,'Activity Settings'!$J$2:$J$200),0) | M5: =IFERROR(XLOOKUP(K5,'Activity Settings'!$M$2:$M$200,'Activity Settings'!$L$2:$L$200),"Knapsack") | N5: =IFERROR(XLOOKUP(J5&"|"&M5,Rates!$E$2:$E$13,Rates!$C$2:$C$13),0) | O5: =L5*N5
A6: Implementation + Onboarding | B6: Stakeholder Alignment Workshops | C6: Review and sign off communication plan with Steering Committee | D6: Stakeholder Map, Communication Strategy Draft | E6: Ensure executive and stakeholder alignment before kickoff. | F6: CX Partner - Change Management SME | G6: Adobe | H6: CX Partner | I6: 1–2 | J6: =IFERROR(XLOOKUP(H6,'Lookups - JourneyDeployment'!$K$3:$K$7,'Lookups - JourneyDeployment'!$L$3:$L$7),"") | K6: =A6&"|"&B6 | L6: =IFERROR(XLOOKUP(K6,'Activity Settings'!$M$2:$M$200,'Activity Settings'!$J$2:$J$200),0) | M6: =IFERROR(XLOOKUP(K6,'Activity Settings'!$M$2:$M$200,'Activity Settings'!$L$2:$L$200),"Knapsack") | N6: =IFERROR(XLOOKUP(J6&"|"&M6,Rates!$E$2:$E$13,Rates!$C$2:$C$13),0) | O6: =L6*N6
A7: Implementation + Onboarding | B7: Program management and coordination | C7: Establish governance tracker and cadence calendar | F7: Project Manager | G7: Knapsack | H7: Project Manager | I7: 1–20 | J7: =IFERROR(XLOOKUP(H7,'Lookups - JourneyDeployment'!$K$3:$K$7,'Lookups - JourneyDeployment'!$L$3:$L$7),"") | K7: =A7&"|"&B7 | L7: =IFERROR(XLOOKUP(K7,'Activity Settings'!$M$2:$M$200,'Activity Settings'!$J$2:$J$200),0) | M7: =IFERROR(XLOOKUP(K7,'Activity Settings'!$M$2:$M$200,'Activity Settings'!$L$2:$L$200),"Knapsack") | N7: =IFERROR(XLOOKUP(J7&"|"&M7,Rates!$E$2:$E$13,Rates!$C$2:$C$13),0) | O7: =L7*N7
A8: Implementation + Onboarding | B8: Program management and coordination | C8: Schedule weekly syncs and milestone reviews | F8: Project Manager | G8: Knapsack | H8: Project Manager | I8: 1–20 | J8: =IFERROR(XLOOKUP(H8,'Lookups - JourneyDeployment'!$K$3:$K$7,'Lookups - JourneyDeployment'!$L$3:$L$7),"") | K8: =A8&"|"&B8 | L8: =IFERROR(XLOOKUP(K8,'Activity Settings'!$M$2:$M$200,'Activity Settings'!$J$2:$J$200),0) | M8: =IFERROR(XLOOKUP(K8,'Activity Settings'!$M$2:$M$200,'Activity Settings'!$L$2:$L$200),"Knapsack") | N8: =IFERROR(XLOOKUP(J8&"|"&M8,Rates!$E$2:$E$13,Rates!$C$2:$C$13),0) | O8: =L8*N8
A9: Implementation + Onboarding | B9: Program management and coordination | C9: Maintain RAID log | F9: Project Manager | G9: Knapsack | H9: Project Manager | I9: 1–20 | J9: =IFERROR(XLOOKUP(H9,'Lookups - JourneyDeployment'!$K$3:$K$7,'Lookups - JourneyDeployment'!$L$3:$L$7),"") | K9: =A9&"|"&B9 | L9: =IFERROR(XLOOKUP(K9,'Activity Settings'!$M$2:$M$200,'Activity Settings'!$J$2:$J$200),0) | M9: =IFERROR(XLOOKUP(K9,'Activity Settings'!$M$2:$M$200,'Activity Settings'!$L$2:$L$200),"Knapsack") | N9: =IFERROR(XLOOKUP(J9&"|"&M9,Rates!$E$2:$E$13,Rates!$C$2:$C$13),0) | O9: =L9*N9
A10: Implementation + Onboarding | B10: Program management and coordination | C10: Prepare Phase 1 exit and readiness report | F10: Project Manager | G10: Knapsack | H10: Project Manager | I10: 1–20 | J10: =IFERROR(XLOOKUP(H10,'Lookups - JourneyDeployment'!$K$3:$K$7,'Lookups - JourneyDeployment'!$L$3:$L$7),"") | K10: =A10&"|"&B10 | L10: =IFERROR(XLOOKUP(K10,'Activity Settings'!$M$2:$M$200,'Activity Settings'!$J$2:$J$200),0) | M10: =IFERROR(XLOOKUP(K10,'Activity Settings'!$M$2:$M$200,'Activity Settings'!$L$2:$L$200),"Knapsack") | N10: =IFERROR(XLOOKUP(J10&"|"&M10,Rates!$E$2:$E$13,Rates!$C$2:$C$13),0) | O10: =L10*N10
A11: Implementation + Onboarding | B11: Program management and coordination | C11: Present status updates to Adobe Steering Committee | D11: Project Governance Tracker, Phase 1 Exit Report | E11: Program coordination, kickoff, and phase review oversight. | F11: Project Manager | G11: Knapsack | H11: Project Manager | I11: 1–20 | J11: =IFERROR(XLOOKUP(H11,'Lookups - JourneyDeployment'!$K$3:$K$7,'Lookups - JourneyDeployment'!$L$3:$L$7),"") | K11: =A11&"|"&B11 | L11: =IFERROR(XLOOKUP(K11,'Activity Settings'!$M$2:$M$200,'Activity Settings'!$J$2:$J$200),0) | M11: =IFERROR(XLOOKUP(K11,'Activity Settings'!$M$2:$M$200,'Activity Settings'!$L$2:$L$200),"Knapsack") | N11: =IFERROR(XLOOKUP(J11&"|"&M11,Rates!$E$2:$E$13,Rates!$C$2:$C$13),0) | O11: =L11*N11
A12: Implementation + Onboarding | B12: Communication Launch Plan | C12: Create internal messaging and visual identity kit | F12: CX Partner - Change Management SME | G12: Adobe | H12: CX Partner | I12: 3–6 | J12: =IFERROR(XLOOKUP(H12,'Lookups - JourneyDeployment'!$K$3:$K$7,'Lookups - JourneyDeployment'!$L$3:$L$7),"") | K12: =A12&"|"&B12 | L12: =IFERROR(XLOOKUP(K12,'Activity Settings'!$M$2:$M$200,'Activity Settings'!$J$2:$J$200),0) | M12: =IFERROR(XLOOKUP(K12,'Activity Settings'!$M$2:$M$200,'Activity Settings'!$L$2:$L$200),"Knapsack") | N12: =IFERROR(XLOOKUP(J12&"|"&M12,Rates!$E$2:$E$13,Rates!$C$2:$C$13),0) | O12: =L12*N12
A13: Implementation + Onboarding | B13: Communication Launch Plan | C13: Develop launch materials (FAQ, deck, announcement) | F13: CX Partner - Change Management SME | G13: Adobe | H13: CX Partner | I13: 3–6 | J13: =IFERROR(XLOOKUP(H13,'Lookups - JourneyDeployment'!$K$3:$K$7,'Lookups - JourneyDeployment'!$L$3:$L$7),"") | K13: =A13&"|"&B13 | L13: =IFERROR(XLOOKUP(K13,'Activity Settings'!$M$2:$M$200,'Activity Settings'!$J$2:$J$200),0) | M13: =IFERROR(XLOOKUP(K13,'Activity Settings'!$M$2:$M$200,'Activity Settings'!$L$2:$L$200),"Knapsack") | N13: =IFERROR(XLOOKUP(J13&"|"&M13,Rates!$E$2:$E$13,Rates!$C$2:$C$13),0) | O13: =L13*N13
A14: Implementation + Onboarding | B14: Communication Launch Plan | C14: Align with design ops for internal brand tone and channels | F14: CX Partner - Change Management SME | G14: Adobe | H14: CX Partner | I14: 3–6 | J14: =IFERROR(XLOOKUP(H14,'Lookups - JourneyDeployment'!$K$3:$K$7,'Lookups - JourneyDeployment'!$L$3:$L$7),"") | K14: =A14&"|"&B14 | L14: =IFERROR(XLOOKUP(K14,'Activity Settings'!$M$2:$M$200,'Activity Settings'!$J$2:$J$200),0) | M14: =IFERROR(XLOOKUP(K14,'Activity Settings'!$M$2:$M$200,'Activity Settings'!$L$2:$L$200),"Knapsack") | N14: =IFERROR(XLOOKUP(J14&"|"&M14,Rates!$E$2:$E$13,Rates!$C$2:$C$13),0) | O14: =L14*N14
A15: Implementation + Onboarding | B15: Communication Launch Plan | C15: Distribute campaign via Adobe internal comms | F15: CX Partner - Change Management SME | G15: Adobe | H15: CX Partner | I15: 3–6 | J15: =IFERROR(XLOOKUP(H15,'Lookups - JourneyDeployment'!$K$3:$K$7,'Lookups - JourneyDeployment'!$L$3:$L$7),"") | K15: =A15&"|"&B15 | L15: =IFERROR(XLOOKUP(K15,'Activity Settings'!$M$2:$M$200,'Activity Settings'!$J$2:$J$200),0) | M15: =IFERROR(XLOOKUP(K15,'Activity Settings'!$M$2:$M$200,'Activity Settings'!$L$2:$L$200),"Knapsack") | N15: =IFERROR(XLOOKUP(J15&"|"&M15,Rates!$E$2:$E$13,Rates!$C$2:$C$13),0) | O15: =L15*N15
A16: Implementation + Onboarding | B16: Communication Launch Plan | C16: Gather feedback and refine messaging | D16: Internal Communication Plan, Branding Package | E16: Launch program messaging, goals, and brand identity across teams. | F16: CX Partner - Change Management SME | G16: Adobe | H16: CX Partner | I16: 3–6 | J16: =IFERROR(XLOOKUP(H16,'Lookups - JourneyDeployment'!$K$3:$K$7,'Lookups - JourneyDeployment'!$L$3:$L$7),"") | K16: =A16&"|"&B16 | L16: =IFERROR(XLOOKUP(K16,'Activity Settings'!$M$2:$M$200,'Activity Settings'!$J$2:$J$200),0) | M16: =IFERROR(XLOOKUP(K16,'Activity Settings'!$M$2:$M$200,'Activity Settings'!$L$2:$L$200),"Knapsack") | N16: =IFERROR(XLOOKUP(J16&"|"&M16,Rates!$E$2:$E$13,Rates!$C$2:$C$13),0) | O16: =L16*N16
A17: Implementation + Onboarding | B17: Preparation | C17: Conduct environment readiness check | F17: Project Manager | G17: Knapsack | H17: Project Manager | I17: 7–10 | J17: =IFERROR(XLOOKUP(H17,'Lookups - JourneyDeployment'!$K$3:$K$7,'Lookups - JourneyDeployment'!$L$3:$L$7),"") | K17: =A17&"|"&B17 | L17: =IFERROR(XLOOKUP(K17,'Activity Settings'!$M$2:$M$200,'Activity Settings'!$J$2:$J$200),0) | M17: =IFERROR(XLOOKUP(K17,'Activity Settings'!$M$2:$M$200,'Activity Settings'!$L$2:$L$200),"Knapsack") | N17: =IFERROR(XLOOKUP(J17&"|"&M17,Rates!$E$2:$E$13,Rates!$C$2:$C$13),0) | O17: =L17*N17
A18: Implementation + Onboarding | B18: Preparation | C18: Validate API and endpoint configuration | F18: Project Manager | G18: Knapsack | H18: Project Manager | I18: 7–10 | J18: =IFERROR(XLOOKUP(H18,'Lookups - JourneyDeployment'!$K$3:$K$7,'Lookups - JourneyDeployment'!$L$3:$L$7),"") | K18: =A18&"|"&B18 | L18: =IFERROR(XLOOKUP(K18,'Activity Settings'!$M$2:$M$200,'Activity Settings'!$J$2:$J$200),0) | M18: =IFERROR(XLOOKUP(K18,'Activity Settings'!$M$2:$M$200,'Activity Settings'!$L$2:$L$200),"Knapsack") | N18: =IFERROR(XLOOKUP(J18&"|"&M18,Rates!$E$2:$E$13,Rates!$C$2:$C$13),0) | O18: =L18*N18
A19: Implementation + Onboarding | B19: Preparation | C19: Verify authentication and permissions access | F19: Project Manager | G19: Knapsack | H19: Project Manager | I19: 7–10 | J19: =IFERROR(XLOOKUP(H19,'Lookups - JourneyDeployment'!$K$3:$K$7,'Lookups - JourneyDeployment'!$L$3:$L$7),"") | K19: =A19&"|"&B19 | L19: =IFERROR(XLOOKUP(K19,'Activity Settings'!$M$2:$M$200,'Activity Settings'!$J$2:$J$200),0) | M19: =IFERROR(XLOOKUP(K19,'Activity Settings'!$M$2:$M$200,'Activity Settings'!$L$2:$L$200),"Knapsack") | N19: =IFERROR(XLOOKUP(J19&"|"&M19,Rates!$E$2:$E$13,Rates!$C$2:$C$13),0) | O19: =L19*N19
A20: Implementation + Onboarding | B20: Preparation | C20: Confirm hosting and network compliance | F20: Project Manager | G20: Knapsack | H20: Project Manager | I20: 7–10 | J20: =IFERROR(XLOOKUP(H20,'Lookups - JourneyDeployment'!$K$3:$K$7,'Lookups - JourneyDeployment'!$L$3:$L$7),"") | K20: =A20&"|"&B20 | L20: =IFERROR(XLOOKUP(K20,'Activity Settings'!$M$2:$M$200,'Activity Settings'!$J$2:$J$200),0) | M20: =IFERROR(XLOOKUP(K20,'Activity Settings'!$M$2:$M$200,'Activity Settings'!$L$2:$L$200),"Knapsack") | N20: =IFERROR(XLOOKUP(J20&"|"&M20,Rates!$E$2:$E$13,Rates!$C$2:$C$13),0) | O20: =L20*N20
A21: Implementation + Onboarding | B21: Preparation | C21: Document results in Technical Readiness Checklist | D21: Technical Readiness Checklist | E21: Verify infrastructure readiness, environment setup, and permissions. | F21: Project Manager | G21: Knapsack | H21: Project Manager | I21: 7–10 | J21: =IFERROR(XLOOKUP(H21,'Lookups - JourneyDeployment'!$K$3:$K$7,'Lookups - JourneyDeployment'!$L$3:$L$7),"") | K21: =A21&"|"&B21 | L21: =IFERROR(XLOOKUP(K21,'Activity Settings'!$M$2:$M$200,'Activity Settings'!$J$2:$J$200),0) | M21: =IFERROR(XLOOKUP(K21,'Activity Settings'!$M$2:$M$200,'Activity Settings'!$L$2:$L$200),"Knapsack") | N21: =IFERROR(XLOOKUP(J21&"|"&M21,Rates!$E$2:$E$13,Rates!$C$2:$C$13),0) | O21: =L21*N21
A22: Implementation + Onboarding | B22: Local install support | C22: Provide installation guide and validation checklist | F22: Senior Solutions Engineer | G22: Knapsack | H22: Engineer | I22: 7–10 | J22: =IFERROR(XLOOKUP(H22,'Lookups - JourneyDeployment'!$K$3:$K$7,'Lookups - JourneyDeployment'!$L$3:$L$7),"") | K22: =A22&"|"&B22 | L22: =IFERROR(XLOOKUP(K22,'Activity Settings'!$M$2:$M$200,'Activity Settings'!$J$2:$J$200),0) | M22: =IFERROR(XLOOKUP(K22,'Activity Settings'!$M$2:$M$200,'Activity Settings'!$L$2:$L$200),"Knapsack") | N22: =IFERROR(XLOOKUP(J22&"|"&M22,Rates!$E$2:$E$13,Rates!$C$2:$C$13),0) | O22: =L22*N22
A23: Implementation + Onboarding | B23: Local install support | C23: Support local environment configuration | F23: Senior Solutions Engineer | G23: Knapsack | H23: Engineer | I23: 7–10 | J23: =IFERROR(XLOOKUP(H23,'Lookups - JourneyDeployment'!$K$3:$K$7,'Lookups - JourneyDeployment'!$L$3:$L$7),"") | K23: =A23&"|"&B23 | L23: =IFERROR(XLOOKUP(K23,'Activity Settings'!$M$2:$M$200,'Activity Settings'!$J$2:$J$200),0) | M23: =IFERROR(XLOOKUP(K23,'Activity Settings'!$M$2:$M$200,'Activity Settings'!$L$2:$L$200),"Knapsack") | N23: =IFERROR(XLOOKUP(J23&"|"&M23,Rates!$E$2:$E$13,Rates!$C$2:$C$13),0) | O23: =L23*N23
A24: Implementation + Onboarding | B24: Local install support | C24: Troubleshoot integration issues | F24: Senior Solutions Engineer | G24: Knapsack | H24: Engineer | I24: 7–10 | J24: =IFERROR(XLOOKUP(H24,'Lookups - JourneyDeployment'!$K$3:$K$7,'Lookups - JourneyDeployment'!$L$3:$L$7),"") | K24: =A24&"|"&B24 | L24: =IFERROR(XLOOKUP(K24,'Activity Settings'!$M$2:$M$200,'Activity Settings'!$J$2:$J$200),0) | M24: =IFERROR(XLOOKUP(K24,'Activity Settings'!$M$2:$M$200,'Activity Settings'!$L$2:$L$200),"Knapsack") | N24: =IFERROR(XLOOKUP(J24&"|"&M24,Rates!$E$2:$E$13,Rates!$C$2:$C$13),0) | O24: =L24*N24
A25: Implementation + Onboarding | B25: Local install support | C25: Validate connectivity with IPE components | F25: Senior Solutions Engineer | G25: Knapsack | H25: Engineer | I25: 7–10 | J25: =IFERROR(XLOOKUP(H25,'Lookups - JourneyDeployment'!$K$3:$K$7,'Lookups - JourneyDeployment'!$L$3:$L$7),"") | K25: =A25&"|"&B25 | L25: =IFERROR(XLOOKUP(K25,'Activity Settings'!$M$2:$M$200,'Activity Settings'!$J$2:$J$200),0) | M25: =IFERROR(XLOOKUP(K25,'Activity Settings'!$M$2:$M$200,'Activity Settings'!$L$2:$L$200),"Knapsack") | N25: =IFERROR(XLOOKUP(J25&"|"&M25,Rates!$E$2:$E$13,Rates!$C$2:$C$13),0) | O25: =L25*N25
A26: Implementation + Onboarding | B26: Local install support | C26: Log and close install-related tickets | D26: Installation Validation Report | E26: Validate local environment setup for Knapsack and IPE components. | F26: Senior Solutions Engineer | G26: Knapsack | H26: Engineer | I26: 7–10 | J26: =IFERROR(XLOOKUP(H26,'Lookups - JourneyDeployment'!$K$3:$K$7,'Lookups - JourneyDeployment'!$L$3:$L$7),"") | K26: =A26&"|"&B26 | L26: =IFERROR(XLOOKUP(K26,'Activity Settings'!$M$2:$M$200,'Activity Settings'!$J$2:$J$200),0) | M26: =IFERROR(XLOOKUP(K26,'Activity Settings'!$M$2:$M$200,'Activity Settings'!$L$2:$L$200),"Knapsack") | N26: =IFERROR(XLOOKUP(J26&"|"&M26,Rates!$E$2:$E$13,Rates!$C$2:$C$13),0) | O26: =L26*N26
A27: Implementation + Onboarding | B27: Component rendering | C27: Validate core Spectrum components rendering | F27: Senior Solutions Engineer | G27: Knapsack | H27: Engineer | I27: 7–10 | J27: =IFERROR(XLOOKUP(H27,'Lookups - JourneyDeployment'!$K$3:$K$7,'Lookups - JourneyDeployment'!$L$3:$L$7),"") | K27: =A27&"|"&B27 | L27: =IFERROR(XLOOKUP(K27,'Activity Settings'!$M$2:$M$200,'Activity Settings'!$J$2:$J$200),0) | M27: =IFERROR(XLOOKUP(K27,'Activity Settings'!$M$2:$M$200,'Activity Settings'!$L$2:$L$200),"Knapsack") | N27: =IFERROR(XLOOKUP(J27&"|"&M27,Rates!$E$2:$E$13,Rates!$C$2:$C$13),0) | O27: =L27*N27
A28: Implementation + Onboarding | B28: Component rendering | C28: Conduct visual and functional QA across environments | F28: Senior Solutions Engineer | G28: Knapsack | H28: Engineer | I28: 7–10 | J28: =IFERROR(XLOOKUP(H28,'Lookups - JourneyDeployment'!$K$3:$K$7,'Lookups - JourneyDeployment'!$L$3:$L$7),"") | K28: =A28&"|"&B28 | L28: =IFERROR(XLOOKUP(K28,'Activity Settings'!$M$2:$M$200,'Activity Settings'!$J$2:$J$200),0) | M28: =IFERROR(XLOOKUP(K28,'Activity Settings'!$M$2:$M$200,'Activity Settings'!$L$2:$L$200),"Knapsack") | N28: =IFERROR(XLOOKUP(J28&"|"&M28,Rates!$E$2:$E$13,Rates!$C$2:$C$13),0) | O28: =L28*N28
A29: Implementation + Onboarding | B29: Component rendering | C29: Compare results with baseline expectations | F29: Senior Solutions Engineer | G29: Knapsack | H29: Engineer | I29: 7–10 | J29: =IFERROR(XLOOKUP(H29,'Lookups - JourneyDeployment'!$K$3:$K$7,'Lookups - JourneyDeployment'!$L$3:$L$7),"") | K29: =A29&"|"&B29 | L29: =IFERROR(XLOOKUP(K29,'Activity Settings'!$M$2:$M$200,'Activity Settings'!$J$2:$J$200),0) | M29: =IFERROR(XLOOKUP(K29,'Activity Settings'!$M$2:$M$200,'Activity Settings'!$L$2:$L$200),"Knapsack") | N29: =IFERROR(XLOOKUP(J29&"|"&M29,Rates!$E$2:$E$13,Rates!$C$2:$C$13),0) | O29: =L29*N29
A30: Implementation + Onboarding | B30: Component rendering | C30: Document rendering test summary report | F30: Senior Solutions Engineer | G30: Knapsack | H30: Engineer | I30: 7–10 | J30: =IFERROR(XLOOKUP(H30,'Lookups - JourneyDeployment'!$K$3:$K$7,'Lookups - JourneyDeployment'!$L$3:$L$7),"") | K30: =A30&"|"&B30 | L30: =IFERROR(XLOOKUP(K30,'Activity Settings'!$M$2:$M$200,'Activity Settings'!$J$2:$J$200),0) | M30: =IFERROR(XLOOKUP(K30,'Activity Settings'!$M$2:$M$200,'Activity Settings'!$L$2:$L$200),"Knapsack") | N30: =IFERROR(XLOOKUP(J30&"|"&M30,Rates!$E$2:$E$13,Rates!$C$2:$C$13),0) | O30: =L30*N30
A31: Implementation + Onboarding | B31: Component rendering | C31: Submit remediation recommendations | D31: Rendering QA Report | E31: Validate successful rendering of Spectrum components across environments. | F31: Senior Solutions Engineer | G31: Knapsack | H31: Engineer | I31: 7–10 | J31: =IFERROR(XLOOKUP(H31,'Lookups - JourneyDeployment'!$K$3:$K$7,'Lookups - JourneyDeployment'!$L$3:$L$7),"") | K31: =A31&"|"&B31 | L31: =IFERROR(XLOOKUP(K31,'Activity Settings'!$M$2:$M$200,'Activity Settings'!$J$2:$J$200),0) | M31: =IFERROR(XLOOKUP(K31,'Activity Settings'!$M$2:$M$200,'Activity Settings'!$L$2:$L$200),"Knapsack") | N31: =IFERROR(XLOOKUP(J31&"|"&M31,Rates!$E$2:$E$13,Rates!$C$2:$C$13),0) | O31: =L31*N31
A32: Implementation + Onboarding | B32: SME support for rendering | C32: Review component architecture and consistency | F32: Subject Matter Expert | G32: Knapsack | H32: SME | I32: 7–10 | J32: =IFERROR(XLOOKUP(H32,'Lookups - JourneyDeployment'!$K$3:$K$7,'Lookups - JourneyDeployment'!$L$3:$L$7),"") | K32: =A32&"|"&B32 | L32: =IFERROR(XLOOKUP(K32,'Activity Settings'!$M$2:$M$200,'Activity Settings'!$J$2:$J$200),0) | M32: =IFERROR(XLOOKUP(K32,'Activity Settings'!$M$2:$M$200,'Activity Settings'!$L$2:$L$200),"Knapsack") | N32: =IFERROR(XLOOKUP(J32&"|"&M32,Rates!$E$2:$E$13,Rates!$C$2:$C$13),0) | O32: =L32*N32
A33: Implementation + Onboarding | B33: SME support for rendering | C33: Audit rendering pipeline and dependency mapping | F33: Subject Matter Expert | G33: Knapsack | H33: SME | I33: 7–10 | J33: =IFERROR(XLOOKUP(H33,'Lookups - JourneyDeployment'!$K$3:$K$7,'Lookups - JourneyDeployment'!$L$3:$L$7),"") | K33: =A33&"|"&B33 | L33: =IFERROR(XLOOKUP(K33,'Activity Settings'!$M$2:$M$200,'Activity Settings'!$J$2:$J$200),0) | M33: =IFERROR(XLOOKUP(K33,'Activity Settings'!$M$2:$M$200,'Activity Settings'!$L$2:$L$200),"Knapsack") | N33: =IFERROR(XLOOKUP(J33&"|"&M33,Rates!$E$2:$E$13,Rates!$C$2:$C$13),0) | O33: =L33*N33
A34: Implementation + Onboarding | B34: SME support for rendering | C34: Validate accessibility compliance | F34: Subject Matter Expert | G34: Knapsack | H34: SME | I34: 7–10 | J34: =IFERROR(XLOOKUP(H34,'Lookups - JourneyDeployment'!$K$3:$K$7,'Lookups - JourneyDeployment'!$L$3:$L$7),"") | K34: =A34&"|"&B34 | L34: =IFERROR(XLOOKUP(K34,'Activity Settings'!$M$2:$M$200,'Activity Settings'!$J$2:$J$200),0) | M34: =IFERROR(XLOOKUP(K34,'Activity Settings'!$M$2:$M$200,'Activity Settings'!$L$2:$L$200),"Knapsack") | N34: =IFERROR(XLOOKUP(J34&"|"&M34,Rates!$E$2:$E$13,Rates!$C$2:$C$13),0) | O34: =L34*N34
A35: Implementation + Onboarding | B35: SME support for rendering | C35: Provide expert input to engineering team | F35: Subject Matter Expert | G35: Knapsack | H35: SME | I35: 7–10 | J35: =IFERROR(XLOOKUP(H35,'Lookups - JourneyDeployment'!$K$3:$K$7,'Lookups - JourneyDeployment'!$L$3:$L$7),"") | K35: =A35&"|"&B35 | L35: =IFERROR(XLOOKUP(K35,'Activity Settings'!$M$2:$M$200,'Activity Settings'!$J$2:$J$200),0) | M35: =IFERROR(XLOOKUP(K35,'Activity Settings'!$M$2:$M$200,'Activity Settings'!$L$2:$L$200),"Knapsack") | N35: =IFERROR(XLOOKUP(J35&"|"&M35,Rates!$E$2:$E$13,Rates!$C$2:$C$13),0) | O35: =L35*N35
A36: Implementation + Onboarding | B36: SME support for rendering | C36: Approve Architecture Validation Log | D36: Architecture Validation Log | E36: SME oversight of rendering logic and architectural consistency. | F36: Subject Matter Expert | G36: Knapsack | H36: SME | I36: 7–10 | J36: =IFERROR(XLOOKUP(H36,'Lookups - JourneyDeployment'!$K$3:$K$7,'Lookups - JourneyDeployment'!$L$3:$L$7),"") | K36: =A36&"|"&B36 | L36: =IFERROR(XLOOKUP(K36,'Activity Settings'!$M$2:$M$200,'Activity Settings'!$J$2:$J$200),0) | M36: =IFERROR(XLOOKUP(K36,'Activity Settings'!$M$2:$M$200,'Activity Settings'!$L$2:$L$200),"Knapsack") | N36: =IFERROR(XLOOKUP(J36&"|"&M36,Rates!$E$2:$E$13,Rates!$C$2:$C$13),0) | O36: =L36*N36
A37: Implementation + Onboarding | B37: Deployment support | C37: Define deployment workflow and CI/CD configuration | F37: Senior Solutions Engineer | G37: Knapsack | H37: Engineer | I37: 15–20 | J37: =IFERROR(XLOOKUP(H37,'Lookups - JourneyDeployment'!$K$3:$K$7,'Lookups - JourneyDeployment'!$L$3:$L$7),"") | K37: =A37&"|"&B37 | L37: =IFERROR(XLOOKUP(K37,'Activity Settings'!$M$2:$M$200,'Activity Settings'!$J$2:$J$200),0) | M37: =IFERROR(XLOOKUP(K37,'Activity Settings'!$M$2:$M$200,'Activity Settings'!$L$2:$L$200),"Knapsack") | N37: =IFERROR(XLOOKUP(J37&"|"&M37,Rates!$E$2:$E$13,Rates!$C$2:$C$13),0) | O37: =L37*N37
A38: Implementation + Onboarding | B38: Deployment support | C38: Create rollback and versioning process | F38: Senior Solutions Engineer | G38: Knapsack | H38: Engineer | I38: 15–20 | J38: =IFERROR(XLOOKUP(H38,'Lookups - JourneyDeployment'!$K$3:$K$7,'Lookups - JourneyDeployment'!$L$3:$L$7),"") | K38: =A38&"|"&B38 | L38: =IFERROR(XLOOKUP(K38,'Activity Settings'!$M$2:$M$200,'Activity Settings'!$J$2:$J$200),0) | M38: =IFERROR(XLOOKUP(K38,'Activity Settings'!$M$2:$M$200,'Activity Settings'!$L$2:$L$200),"Knapsack") | N38: =IFERROR(XLOOKUP(J38&"|"&M38,Rates!$E$2:$E$13,Rates!$C$2:$C$13),0) | O38: =L38*N38
A39: Implementation + Onboarding | B39: Deployment support | C39: Run initial deployment test | F39: Senior Solutions Engineer | G39: Knapsack | H39: Engineer | I39: 15–20 | J39: =IFERROR(XLOOKUP(H39,'Lookups - JourneyDeployment'!$K$3:$K$7,'Lookups - JourneyDeployment'!$L$3:$L$7),"") | K39: =A39&"|"&B39 | L39: =IFERROR(XLOOKUP(K39,'Activity Settings'!$M$2:$M$200,'Activity Settings'!$J$2:$J$200),0) | M39: =IFERROR(XLOOKUP(K39,'Activity Settings'!$M$2:$M$200,'Activity Settings'!$L$2:$L$200),"Knapsack") | N39: =IFERROR(XLOOKUP(J39&"|"&M39,Rates!$E$2:$E$13,Rates!$C$2:$C$13),0) | O39: =L39*N39
A40: Implementation + Onboarding | B40: Deployment support | C40: Record metrics against success criteria | F40: Senior Solutions Engineer | G40: Knapsack | H40: Engineer | I40: 15–20 | J40: =IFERROR(XLOOKUP(H40,'Lookups - JourneyDeployment'!$K$3:$K$7,'Lookups - JourneyDeployment'!$L$3:$L$7),"") | K40: =A40&"|"&B40 | L40: =IFERROR(XLOOKUP(K40,'Activity Settings'!$M$2:$M$200,'Activity Settings'!$J$2:$J$200),0) | M40: =IFERROR(XLOOKUP(K40,'Activity Settings'!$M$2:$M$200,'Activity Settings'!$L$2:$L$200),"Knapsack") | N40: =IFERROR(XLOOKUP(J40&"|"&M40,Rates!$E$2:$E$13,Rates!$C$2:$C$13),0) | O40: =L40*N40
...

Sheet Summary
A1: Estimation Summary
A3: Delivery Model | B3: =Inputs!$B$3 | D3: Total Hours | E3: =SUM('Activity Settings'!$I$2:$I$200)
A4: Journey | B4: =Inputs!$B$4 | D4: Total Cost | E4: =SUM('WBS - Estimate'!$O$2:$O$500)
A5: Deployment | B5: =Inputs!$B$5
A6: Default Complexity | B6: =Inputs!$B$6
A7: Readiness Level | B7: =Inputs!$B$8
A8: Readiness Multiplier | B8: =Inputs!$B$7
A11: Hours & Cost by Phase
A12: Phase | B12: Hours | C12: Cost
A13: Implementation + Onboarding | B13: =SUMIFS('Activity Settings'!$I$2:$I$200,'Activity Settings'!$A$2:$A$200,$A13) | C13: =SUMIFS('WBS - Estimate'!$O$2:$O$500,'WBS - Estimate'!$A$2:$A$500,$A13)
A14: Scaled Rollout and Adoption | B14: =SUMIFS('Activity Settings'!$I$2:$I$200,'Activity Settings'!$A$2:$A$200,$A14) | C14: =SUMIFS('WBS - Estimate'!$O$2:$O$500,'WBS - Estimate'!$A$2:$A$500,$A14)
A15: Optimization and Continued Support | B15: =SUMIFS('Activity Settings'!$I$2:$I$200,'Activity Settings'!$A$2:$A$200,$A15) | C15: =SUMIFS('WBS - Estimate'!$O$2:$O$500,'WBS - Estimate'!$A$2:$A$500,$A15)
A18: Hours & Cost by Provider
A19: Provider | B19: Hours | C19: Cost
A20: Knapsack | B20: =SUMIF('WBS - Estimate'!$M$2:$M$500,$A20,'WBS - Estimate'!$L$2:$L$500) | C20: =SUMIF('WBS - Estimate'!$M$2:$M$500,$A20,'WBS - Estimate'!$O$2:$O$500)
A21: Client/SCE | B21: =SUMIF('WBS - Estimate'!$M$2:$M$500,$A21,'WBS - Estimate'!$L$2:$L$500) | C21: =SUMIF('WBS - Estimate'!$M$2:$M$500,$A21,'WBS - Estimate'!$O$2:$O$500)
A24: Hours & Cost by Standard Role
A25: Standard Role | B25: Hours | C25: Cost
A26: CX Partner | B26: =SUMIF('WBS - Estimate'!$J$2:$J$500,$A26,'WBS - Estimate'!$L$2:$L$500) | C26: =SUMIF('WBS - Estimate'!$J$2:$J$500,$A26,'WBS - Estimate'!$O$2:$O$500)
A27: Project Manager | B27: =SUMIF('WBS - Estimate'!$J$2:$J$500,$A27,'WBS - Estimate'!$L$2:$L$500) | C27: =SUMIF('WBS - Estimate'!$J$2:$J$500,$A27,'WBS - Estimate'!$O$2:$O$500)
A28: Solution Analyst | B28: =SUMIF('WBS - Estimate'!$J$2:$J$500,$A28,'WBS - Estimate'!$L$2:$L$500) | C28: =SUMIF('WBS - Estimate'!$J$2:$J$500,$A28,'WBS - Estimate'!$O$2:$O$500)
A29: Senior Solution Analyst | B29: =SUMIF('WBS - Estimate'!$J$2:$J$500,$A29,'WBS - Estimate'!$L$2:$L$500) | C29: =SUMIF('WBS - Estimate'!$J$2:$J$500,$A29,'WBS - Estimate'!$O$2:$O$500)
A30: SME | B30: =SUMIF('WBS - Estimate'!$J$2:$J$500,$A30,'WBS - Estimate'!$L$2:$L$500) | C30: =SUMIF('WBS - Estimate'!$J$2:$J$500,$A30,'WBS - Estimate'!$O$2:$O$500)
A31: Executive | B31: =SUMIF('WBS - Estimate'!$J$2:$J$500,$A31,'WBS - Estimate'!$L$2:$L$500) | C31: =SUMIF('WBS - Estimate'!$J$2:$J$500,$A31,'WBS - Estimate'!$O$2:$O$500)

Sheet RAID Log
A1: ID | B1: Type | C1: Title | D1: Description | E1: Owner | F1: Impact (1-5) | G1: Probability (1-5) | H1: Score | I1: Status | J1: Mitigation / Next Steps | K1: Due Date | L1: Date Opened | M1: Date Closed | N1: Notes
A2: 1 | H2: =IF(OR(F2="",G2=""),"",F2*G2)
A3: 2 | H3: =IF(OR(F3="",G3=""),"",F3*G3)
A4: 3 | H4: =IF(OR(F4="",G4=""),"",F4*G4)
A5: 4 | H5: =IF(OR(F5="",G5=""),"",F5*G5)
A6: 5 | H6: =IF(OR(F6="",G6=""),"",F6*G6)
A7: 6 | H7: =IF(OR(F7="",G7=""),"",F7*G7)
A8: 7 | H8: =IF(OR(F8="",G8=""),"",F8*G8)
A9: 8 | H9: =IF(OR(F9="",G9=""),"",F9*G9)
A10: 9 | H10: =IF(OR(F10="",G10=""),"",F10*G10)
A11: 10 | H11: =IF(OR(F11="",G11=""),"",F11*G11)
A12: 11 | H12: =IF(OR(F12="",G12=""),"",F12*G12)
A13: 12 | H13: =IF(OR(F13="",G13=""),"",F13*G13)
... A201: 200 | H201: =IF(OR(F201="",G201=""),"",F201*G201)

Sheet Instructions - Adobe 
A1: Adobe Resource Planning Model v2.0 — How to:
A3: 1) Review the Plan Tab
A4: - Milestone Plan Tab drives the Proposed Solutions tab: Rollups by Role for review
A5: 2) Adjust the Accountable Party Column F
A6: - Amber took a first pass at the scrub - Angelie and team take it away!
A7: 3 ) Review the Summary Tab to understand the impact on the Resource Model
A8: - The RACI align with where we land on scope in the Procurement phase we are currently in

Sheet Milestone Plan
A1: Line # | B1: Milestone (Activity) | C1: Phase (auto) | D1: Deliverable (auto) | E1: Description | F1: Knapsack Role Description | G1: Accountable Party | H1: Role | I1: Effort Type | J1: Effort Value | K1: Complexity | L1: Calc Hours | M1: Weeks (FTE) | N1: Start Date | O1: End Date | P1: Hourly Rate | Q1: Daily Rate | R1: Cost (auto) | S1: Notes | T1: Scenario Hour Mult. | U1: Scenario Rate Mult. | V1: Contingency % | W1: Final Hours (auto) | X1: Adj. Hourly Rate | Y1: Adj. Cost (auto) | Z1: Review Notes
A2: 1 | B2: Program management and Steering Committee coordination | C2: {=IFERROR(INDEX(Milestones!$A:$A, MATCH($B2, Milestones!$B:$B, 0)), "")} | D2: {=IFERROR(INDEX(Milestones!$C:$C, MATCH($B2, Milestones!$B:$B, 0)), "")} | E2: Kickoff, bi-weekly stand-ups, monthly reports, phase gate reviews | F2: {=IFERROR(INDEX(Milestones!$E:$E, MATCH($B2, Milestones!$B:$B, 0)), "")} | G2: Adobe | H2: {=IFERROR(INDEX(Milestones!$E:$E, MATCH($B2, Milestones!$B:$B, 0)), "")} | I2: FTE | J2: 0.01 | K2: Low | L2: 100 | M2: =IF($I2="FTE", Assumptions!$B$3, "") | N2: {=IFERROR(INDEX(Milestones!$F:$F, MATCH($B2, Milestones!$B:$B, 0)), "")} | O2: {=IFERROR(INDEX(Milestones!$G:$G, MATCH($B2, Milestones!$B:$B, 0)), "")} | P2: {=IFERROR(INDEX('Lookups - Rates'!$D:$D, MATCH($G2&"|"&$H2, 'Lookups - Rates'!$Z:$Z, 0)), "")} | Q2: {=IFERROR(INDEX('Lookups - Rates'!$E:$E, MATCH($G2&"|"&$H2, 'Lookups - Rates'!$Z:$Z, 0)), "")} | R2: =LET(ev,$J2, ch,$L2, hr,$P2, dr,$Q2, hpday,Assumptions!$B$2, hpw,Assumptions!$B$3, w,$M2, hrs, IF($I2="Hours", ev, IF($I2="Days", ev*IF(dr>0, dr/hr, hpday), IF($I2="FTE", ev*hpw*w, ch))), IF(hrs="", "", hrs*hr)) | T2: {=XLOOKUP(Scenario_Selected, INDEX(Scenario_Table,0,1), INDEX(Scenario_Table,0,2))} | U2: {=XLOOKUP(Scenario_Selected, INDEX(Scenario_Table,0,1), INDEX(Scenario_Table,0,3))} | V2: {=XLOOKUP(Scenario_Selected, INDEX(Scenario_Table,0,1), INDEX(Scenario_Table,0,4))} | W2: {=LET(ev,$J2, ch,$L2, et,$I2, dr,$Q2, hpday,Assumptions!$B$2, hpw,Assumptions!$B$3, w,$M2,hm,INDIRECT("R[0]C[0]",FALSE),hrs, IF(et="Hours", ev, IF(et="Days", ev*IF(dr>0, dr/$P2, hpday), IF(et="FTE", ev*hpw*w, ch))), IF(hrs="", "", hrs*hm))} | X2: =IF($P2="","", $P2*INDIRECT("R[0]C[-3]",FALSE)) | Y2: =IF(INDIRECT("R[0]C[-1]",FALSE)="","", INDIRECT("R[0]C[-2]",FALSE)*INDIRECT("R[0]C[-1]",FALSE)*(1+INDIRECT("R[0]C[-3]",FALSE))) | Z2: potentially
A3: 2 | B3: Facilitating and supporting deliverables | C3: {=IFERROR(INDEX(Milestones!$A:$A, MATCH($B3, Milestones!$B:$B, 0)), "")} | D3: {=IFERROR(INDEX(Milestones!$C:$C, MATCH($B3, Milestones!$B:$B, 0)), "")} | E3: Track adoption metrics, stakeholder engagement, and training completion | F3: {=IFERROR(INDEX(Milestones!$E:$E, MATCH($B3, Milestones!$B:$B, 0)), "")} | G3: Adobe | H3: Adobe | I3: FTE | J3: 0.03 | K3: Medium | L3: {=IF($K3="","", IFERROR(IFS($K3="Low", INDEX('Lookups - Complexity'!$C:$C, MATCH($B3, 'Lookups - Complexity'!$B:$B,0)), $K3="Medium", INDEX('Lookups - Complexity'!$D:$D, MATCH($B3, 'Lookups - Complexity'!$B:$B,0)), $K3="High", INDEX('Lookups - Complexity'!$E:$E, MATCH($B3, 'Lookups - Complexity'!$B:$B,0))), ""))} | M3: =IF($I3="FTE", Assumptions!$B$3, "") | N3: {=IFERROR(INDEX(Milestones!$F:$F, MATCH($B3, Milestones!$B:$B, 0)), "")} | O3: {=IFERROR(INDEX(Milestones!$G:$G, MATCH($B3, Milestones!$B:$B, 0)), "")} | P3: {=IFERROR(INDEX('Lookups - Rates'!$D:$D, MATCH($G3&"|"&$H3, 'Lookups - Rates'!$Z:$Z, 0)), "")} | Q3: {=IFERROR(INDEX('Lookups - Rates'!$E:$E, MATCH($G3&"|"&$H3, 'Lookups - Rates'!$Z:$Z, 0)), "")} | R3: =LET(ev,$J3, ch,$L3, hr,$P3, dr,$Q3, hpday,Assumptions!$B$2, hpw,Assumptions!$B$3, w,$M3, hrs, IF($I3="Hours", ev, IF($I3="Days", ev*IF(dr>0, dr/hr, hpday), IF($I3="FTE", ev*hpw*w, ch))), IF(hrs="", "", hrs*hr)) | T3: {=XLOOKUP(Scenario_Selected, INDEX(Scenario_Table,0,1), INDEX(Scenario_Table,0,2))} | U3: {=XLOOKUP(Scenario_Selected, INDEX(Scenario_Table,0,1), INDEX(Scenario_Table,0,3))} | V3: {=XLOOKUP(Scenario_Selected, INDEX(Scenario_Table,0,1), INDEX(Scenario_Table,0,4))} | W3: {=LET(ev,$J3, ch,$L3, et,$I3, dr,$Q3, hpday,Assumptions!$B$2, hpw,Assumptions!$B$3, w,$M3,hm,INDIRECT("R[0]C[0]",FALSE),hrs, IF(et="Hours", ev, IF(et="Days", ev*IF(dr>0, dr/$P3, hpday), IF(et="FTE", ev*hpw*w, ch))), IF(hrs="", "", hrs*hm))} | X3: =IF($P3="","", $P3*INDIRECT("R[0]C[-3]",FALSE)) | Y3: =IF(INDIRECT("R[0]C[-1]",FALSE)="","", INDIRECT("R[0]C[-2]",FALSE)*INDIRECT("R[0]C[-1]",FALSE)*(1+INDIRECT("R[0]C[-3]",FALSE))) | Z3: typically owned by the team - partnership with Program management + leads
A4: 3 | B4: Stakeholder Alignment Workshops | C4: {=IFERROR(INDEX(Milestones!$A:$A, MATCH($B4, Milestones!$B:$B, 0)), "")} | D4: {=IFERROR(INDEX(Milestones!$C:$C, MATCH($B4, Milestones!$B:$B, 0)), "")} | E4: Ensure executive and stakeholder alignment before kickoff. | F4: {=IFERROR(INDEX(Milestones!$E:$E, MATCH($B4, Milestones!$B:$B, 0)), "")} | G4: Adobe | H4: Adobe | I4: FTE | J4: 0.03 | K4: Medium | L4: {=IF($K4="","", IFERROR(IFS($K4="Low", INDEX('Lookups - Complexity'!$C:$C, MATCH($B4, 'Lookups - Complexity'!$B:$B,0)), $K4="Medium", INDEX('Lookups - Complexity'!$D:$D, MATCH($B4, 'Lookups - Complexity'!$B:$B,0)), $K4="High", INDEX('Lookups - Complexity'!$E:$E, MATCH($B4, 'Lookups - Complexity'!$B:$B,0))), ""))} | M4: =IF($I4="FTE", Assumptions!$B$3, "") | N4: {=IFERROR(INDEX(Milestones!$F:$F, MATCH($B4, Milestones!$B:$B, 0)), "")} | O4: {=IFERROR(INDEX(Milestones!$G:$G, MATCH($B4, Milestones!$B:$B, 0)), "")} | P4: {=IFERROR(INDEX('Lookups - Rates'!$D:$D, MATCH($G4&"|"&$H4, 'Lookups - Rates'!$Z:$Z, 0)), "")} | Q4: {=IFERROR(INDEX('Lookups - Rates'!$E:$E, MATCH($G4&"|"&$H4, 'Lookups - Rates'!$Z:$Z, 0)), "")} | R4: =LET(ev,$J4, ch,$L4, hr,$P4, dr,$Q4, hpday,Assumptions!$B$2, hpw,Assumptions!$B$3, w,$M4, hrs, IF($I4="Hours", ev, IF($I4="Days", ev*IF(dr>0, dr/hr, hpday), IF($I4="FTE", ev*hpw*w, ch))), IF(hrs="", "", hrs*hr)) | T4: {=XLOOKUP(Scenario_Selected, INDEX(Scenario_Table,0,1), INDEX(Scenario_Table,0,2))} | U4: {=XLOOKUP(Scenario_Selected, INDEX(Scenario_Table,0,1), INDEX(Scenario_Table,0,3))} | V4: {=XLOOKUP(Scenario_Selected, INDEX(Scenario_Table,0,1), INDEX(Scenario_Table,0,4))} | W4: {=LET(ev,$J4, ch,$L4, et,$I4, dr,$Q4, hpday,Assumptions!$B$2, hpw,Assumptions!$B$3, w,$M4,hm,INDIRECT("R[0]C[0]",FALSE),hrs, IF(et="Hours", ev, IF(et="Days", ev*IF(dr>0, dr/$P4, hpday), IF(et="FTE", ev*hpw*w, ch))), IF(hrs="", "", hrs*hm))} | X4: =IF($P4="","", $P4*INDIRECT("R[0]C[-3]",FALSE)) | Y4: =IF(INDIRECT("R[0]C[-1]",FALSE)="","", INDIRECT("R[0]C[-2]",FALSE)*INDIRECT("R[0]C[-1]",FALSE)*(1+INDIRECT("R[0]C[-3]",FALSE))) | Z4: Product Owners, etc.
A5: 4 | B5: Change Readiness Assessment | C5: {=IFERROR(INDEX(Milestones!$A:$A, MATCH($B5, Milestones!$B:$B, 0)), "")} | D5: {=IFERROR(INDEX(Milestones!$A:$A, MATCH($B5, Milestones!$B:$B, 0)), "")} | E5: Assess cultural, technical, and operational readiness prior to implementation. | F5: {=IFERROR(INDEX(Milestones!$E:$E, MATCH($B5, Milestones!$B:$B, 0)), "")} | G5: Adobe | H5: CX Partner - Change Management SME | I5: FTE | J5: 0.03 | K5: Medium | L5: 16 | M5: =IF($I5="FTE", Assumptions!$B$3, "") | N5: {=IFERROR(INDEX(Milestones!$F:$F, MATCH($B5, Milestones!$B:$B, 0)), "")} | O5: {=IFERROR(INDEX(Milestones!$G:$G, MATCH($B5, Milestones!$B:$B, 0)), "")} | P5: {=IFERROR(INDEX('Lookups - Rates'!$D:$D, MATCH($G5&"|"&$H5, 'Lookups - Rates'!$Z:$Z, 0)), "")} | Q5: {=IFERROR(INDEX('Lookups - Rates'!$E:$E, MATCH($G5&"|"&$H5, 'Lookups - Rates'!$Z:$Z, 0)), "")} | R5: =LET(ev,$J5, ch,$L5, hr,$P5, dr,$Q5, hpday,Assumptions!$B$2, hpw,Assumptions!$B$3, w,$M5, hrs, IF($I5="Hours", ev, IF($I5="Days", ev*IF(dr>0, dr/hr, hpday), IF($I5="FTE", ev*hpw*w, ch))), IF(hrs="", "", hrs*hr)) | T5: {=XLOOKUP(Scenario_Selected, INDEX(Scenario_Table,0,1), INDEX(Scenario_Table,0,2))} | U5: {=XLOOKUP(Scenario_Selected, INDEX(Scenario_Table,0,1), INDEX(Scenario_Table,0,3))} | V5: {=XLOOKUP(Scenario_Selected, INDEX(Scenario_Table,0,1), INDEX(Scenario_Table,0,4))} | W5: {=LET(ev,$J5, ch,$L5, et,$I5, dr,$Q5, hpday,Assumptions!$B$2, hpw,Assumptions!$B$3, w,$M5,hm,INDIRECT("R[0]C[0]",FALSE),hrs, IF(et="Hours", ev, IF(et="Days", ev*IF(dr>0, dr/$P5, hpday), IF(et="FTE", ev*hpw*w, ch))), IF(hrs="", "", hrs*hm))} | X5: =IF($P5="","", $P5*INDIRECT("R[0]C[-3]",FALSE)) | Y5: =IF(INDIRECT("R[0]C[-1]",FALSE)="","", INDIRECT("R[0]C[-2]",FALSE)*INDIRECT("R[0]C[-1]",FALSE)*(1+INDIRECT("R[0]C[-3]",FALSE))) | Z5: The Spectrum team will be fine - external to Spectrum will be limited to the documentation. Programming is in place to support this | AA5: Amber to share the readiness survey
A6: 5 | B6: Program management and coordination | C6: {=IFERROR(INDEX(Milestones!$A:$A, MATCH($B6, Milestones!$B:$B, 0)), "")} | D6: {=IFERROR(INDEX(Milestones!$C:$C, MATCH($B6, Milestones!$B:$B, 0)), "")} | E6: Program coordination, kickoff, and phase review oversight | F6: {=IFERROR(INDEX(Milestones!$E:$E, MATCH($B6, Milestones!$B:$B, 0)), "")} | G6: Knapsack | H6: {=IFERROR(INDEX(Milestones!$E:$E, MATCH($B6, Milestones!$B:$B, 0)), "")} | I6: FTE | J6: 0.03 | K6: Medium | L6: {=IF($K6="","", IFERROR(IFS($K6="Low", INDEX('Lookups - Complexity'!$C:$C, MATCH($B6, 'Lookups - Complexity'!$B:$B,0)), $K6="Medium", INDEX('Lookups - Complexity'!$D:$D, MATCH($B6, 'Lookups - Complexity'!$B:$B,0)), $K6="High", INDEX('Lookups - Complexity'!$E:$E, MATCH($B6, 'Lookups - Complexity'!$B:$B,0))), ""))} | M6: =IF($I6="FTE", Assumptions!$B$3, "") | N6: {=IFERROR(INDEX(Milestones!$F:$F, MATCH($B6, Milestones!$B:$B, 0)), "")} | O6: {=IFERROR(INDEX(Milestones!$G:$G, MATCH($B6, Milestones!$B:$B, 0)), "")} | P6: {=IFERROR(INDEX('Lookups - Rates'!$D:$D, MATCH($G6&"|"&$H6, 'Lookups - Rates'!$Z:$Z, 0)), "")} | Q6: {=IFERROR(INDEX('Lookups - Rates'!$E:$E, MATCH($G6&"|"&$H6, 'Lookups - Rates'!$Z:$Z, 0)), "")} | R6: =LET(ev,$J6, ch,$L6, hr,$P6, dr,$Q6, hpday,Assumptions!$B$2, hpw,Assumptions!$B$3, w,$M6, hrs, IF($I6="Hours", ev, IF($I6="Days", ev*IF(dr>0, dr/hr, hpday), IF($I6="FTE", ev*hpw*w, ch))), IF(hrs="", "", hrs*hr)) | T6: {=XLOOKUP(Scenario_Selected, INDEX(Scenario_Table,0,1), INDEX(Scenario_Table,0,2))} | U6: {=XLOOKUP(Scenario_Selected, INDEX(Scenario_Table,0,1), INDEX(Scenario_Table,0,3))} | V6: {=XLOOKUP(Scenario_Selected, INDEX(Scenario_Table,0,1), INDEX(Scenario_Table,0,4))} | W6: {=LET(ev,$J6, ch,$L6, et,$I6, dr,$Q6, hpday,Assumptions!$B$2, hpw,Assumptions!$B$3, w,$M6,hm,INDIRECT("R[0]C[0]",FALSE),hrs, IF(et="Hours", ev, IF(et="Days", ev*IF(dr>0, dr/$P6, hpday), IF(et="FTE", ev*hpw*w, ch))), IF(hrs="", "", hrs*hm))} | X6: =IF($P6="","", $P6*INDIRECT("R[0]C[-3]",FALSE)) | Y6: =IF(INDIRECT("R[0]C[-1]",FALSE)="","", INDIRECT("R[0]C[-2]",FALSE)*INDIRECT("R[0]C[-1]",FALSE)*(1+INDIRECT("R[0]C[-3]",FALSE))) | Z6: @ADOBE - WE HAVE INCLUDED OUR PROJECT MANAGER RESOURCE HERE TO SUPPORT AND THEY WILL TAKE DIRECTION FROM ANDREW AND I AS CX PARTNERS TO KEEP COST DOWN AND STILL PROVIDE YOU WITH THE VALUE OF CX LED PROGRAM MANAGEMENT. THEY WILL NEED TO BE IN LOCK STEP WITH YOUR PROJECT MANAGER FROM ROW 1 OF THIS PLAN. 10.28 @ADOBE - what is the final answer on this? Is Adobe Accountable OR do you want/need Knapsack support. Notes from previous review. Our Program Managers are stretched quite thin - IF there is an opportunity to leverage a Project Manager alongside the FDE we can consider it - let's align on the terms. Option for contractor spend
A7: 6 | B7: Communication Launch Plan | C7: {=IFERROR(INDEX(Milestones!$A:$A, MATCH($B7, Milestones!$B:$B, 0)), "")} | D7: {=IFERROR(INDEX(Milestones!$C:$C, MATCH($B7, Milestones!$B:$B, 0)), "")} | E7: Launch program messaging, goals, and brand identity across teams. | F7: {=IFERROR(INDEX(Milestones!$E:$E, MATCH($B7, Milestones!$B:$B, 0)), "")} | G7: Adobe | H7: Adobe | I7: FTE | J7: 0.05 | K7: High | L7: {=IF($K7="","", IFERROR(IFS($K7="Low", INDEX('Lookups - Complexity'!$C:$C, MATCH($B7, 'Lookups - Complexity'!$B:$B,0)), $K7="Medium", INDEX('Lookups - Complexity'!$D:$D, MATCH($B7, 'Lookups - Complexity'!$B:$B,0)), $K7="High", INDEX('Lookups - Complexity'!$E:$E, MATCH($B7, 'Lookups - Complexity'!$B:$B,0))), ""))} | M7: =IF($I7="FTE", Assumptions!$B$3, "") | N7: {=IFERROR(INDEX(Milestones!$F:$F, MATCH($B7, Milestones!$B:$B, 0)), "")} | O7: {=IFERROR(INDEX(Milestones!$G:$G, MATCH($B7, Milestones!$B:$B, 0)), "")} | P7: {=IFERROR(INDEX('Lookups - Rates'!$D:$D, MATCH($G7&"|"&$H7, 'Lookups - Rates'!$Z:$Z, 0)), "")} | Q7: {=IFERROR(INDEX('Lookups - Rates'!$E:$E, MATCH($G7&"|"&$H7, 'Lookups - Rates'!$Z:$Z, 0)), "")} | R7: =LET(ev,$J7, ch,$L7, hr,$P7, dr,$Q7, hpday,Assumptions!$B$2, hpw,Assumptions!$B$3, w,$M7, hrs, IF($I7="Hours", ev, IF($I7="Days", ev*IF(dr>0, dr/hr, hpday), IF($I7="FTE", ev*hpw*w, ch))), IF(hrs="", "", hrs*hr)) | T7: {=XLOOKUP(Scenario_Selected, INDEX(Scenario_Table,0,1), INDEX(Scenario_Table,0,2))} | U7: {=XLOOKUP(Scenario_Selected, INDEX(Scenario_Table,0,1), INDEX(Scenario_Table,0,3))} | V7: {=XLOOKUP(Scenario_Selected, INDEX(Scenario_Table,0,1), INDEX(Scenario_Table,0,4))} | W7: {=LET(ev,$J7, ch,$L7, et,$I7, dr,$Q7, hpday,Assumptions!$B$2, hpw,Assumptions!$B$3, w,$M7,hm,INDIRECT("R[0]C[0]",FALSE),hrs, IF(et="Hours", ev, IF(et="Days", ev*IF(dr>0, dr/$P7, hpday), IF(et="FTE", ev*hpw*w, ch))), IF(hrs="", "", hrs*hm))} | X7: =IF($P7="","", $P7*INDIRECT("R[0]C[-3]",FALSE)) | Y7: =IF(INDIRECT("R[0]C[-1]",FALSE)="","", INDIRECT("R[0]C[-2]",FALSE)*INDIRECT("R[0]C[-1]",FALSE)*(1+INDIRECT("R[0]C[-3]",FALSE)))
A8: 7 | B8: Preparation | C8: {=IFERROR(INDEX(Milestones!$A:$A, MATCH($B8, Milestones!$B:$B, 0)), "")} | D8: {=IFERROR(INDEX(Milestones!$C:$C, MATCH($B8, Milestones!$B:$B, 0)), "")} | E8: Verify infrastructure readiness, environment setup, and permissions | F8: {=IFERROR(INDEX(Milestones!$E:$E, MATCH($B8, Milestones!$B:$B, 0)), "")} | G8: Knapsack | H8: {=IFERROR(INDEX(Milestones!$E:$E, MATCH($B8, Milestones!$B:$B, 0)), "")} | I8: FTE | J8: 0.025 | K8: Medium | L8: {=IF($K8="","", IFERROR(IFS($K8="Low", INDEX('Lookups - Complexity'!$C:$C, MATCH($B8, 'Lookups - Complexity'!$B:$B,0)), $K8="Medium", INDEX('Lookups - Complexity'!$D:$D, MATCH($B8, 'Lookups - Complexity'!$B:$B,0)), $K8="High", INDEX('Lookups - Complexity'!$E:$E, MATCH($B8, 'Lookups - Complexity'!$B:$B,0))), ""))} | M8: =IF($I8="FTE", Assumptions!$B$3, "") | N8: {=IFERROR(INDEX(Milestones!$F:$F, MATCH($B8, Milestones!$B:$B, 0)), "")} | O8: {=IFERROR(INDEX(Milestones!$G:$G, MATCH($B8, Milestones!$B:$B, 0)), "")} | P8: {=IFERROR(INDEX('Lookups - Rates'!$D:$D, MATCH($G8&"|"&$H8, 'Lookups - Rates'!$Z:$Z, 0)), "")} | Q8: {=IFERROR(INDEX('Lookups - Rates'!$E:$E, MATCH($G8&"|"&$H8, 'Lookups - Rates'!$Z:$Z, 0)), "")} | R8: =LET(ev,$J8, ch,$L8, hr,$P8, dr,$Q8, hpday,Assumptions!$B$2, hpw,Assumptions!$B$3, w,$M8, hrs, IF($I8="Hours", ev, IF($I8="Days", ev*IF(dr>0, dr/hr, hpday), IF($I8="FTE", ev*hpw*w, ch))), IF(hrs="", "", hrs*hr)) | T8: {=XLOOKUP(Scenario_Selected, INDEX(Scenario_Table,0,1), INDEX(Scenario_Table,0,2))} | U8: {=XLOOKUP(Scenario_Selected, INDEX(Scenario_Table,0,1), INDEX(Scenario_Table,0,3))} | V8: {=XLOOKUP(Scenario_Selected, INDEX(Scenario_Table,0,1), INDEX(Scenario_Table,0,4))} | W8: {=LET(ev,$J8, ch,$L8, et,$I8, dr,$Q8, hpday,Assumptions!$B$2, hpw,Assumptions!$B$3, w,$M8,hm,INDIRECT("R[0]C[0]",FALSE),hrs, IF(et="Hours", ev, IF(et="Days", ev*IF(dr>0, dr/$P8, hpday), IF(et="FTE", ev*hpw*w, ch))), IF(hrs="", "", hrs*hm))} | X8: =IF($P8="","", $P8*INDIRECT("R[0]C[-3]",FALSE)) | Y8: =IF(INDIRECT("R[0]C[-1]",FALSE)="","", INDIRECT("R[0]C[-2]",FALSE)*INDIRECT("R[0]C[-1]",FALSE)*(1+INDIRECT("R[0]C[-3]",FALSE)))
